File: data/am1.csv
Results Table 1;;;;;
;;;;;
;;;;;
;Aço 1016;;;;
;Time;Displacement;Force;Tensile strain (Strain 2);Tensile stress
;(s);(mm);(kN);(mm/mm);(MPa)
;0.0000;-0.00472;0.00508;0.00000;0.21382
;0.1260;-0.00149;0.03126;0.00001;1.31571
;0.1620;0.00090;0.06370;0.00001;2.68128
;0.2200;0.00544;0.09044;0.00001;3.80671
;0.4140;0.01937;0.11404;0.00003;4.79994
;0.6240;0.03265;0.13740;0.00003;5.78333
;0.7480;0.04024;0.16103;0.00003;6.77780
;0.8120;0.04401;0.18717;0.00004;7.87825
;0.8920;0.04891;0.21285;0.00004;8.95902
;1.0020;0.05542;0.23678;0.00005;9.96627
;1.1000;0.06134;0.26094;0.00005;10.98307
;1.1820;0.06613;0.28531;0.00005;12.00895
;1.2540;0.07055;0.31093;0.00006;13.08739
;1.3260;0.07486;0.33674;0.00006;14.17362
;1.3860;0.07856;0.36282;0.00006;15.27112
;1.4400;0.08179;0.39171;0.00006;16.48711
;1.4940;0.08502;0.41958;0.00007;17.66030
;1.5480;0.08825;0.44853;0.00007;18.87878
;1.6020;0.09148;0.47823;0.00007;20.12914
;1.6560;0.09471;0.50721;0.00008;21.34855
;1.7100;0.09794;0.53795;0.00008;22.64282
;1.7620;0.10110;0.56909;0.00009;23.95330
;1.8080;0.10385;0.59760;0.00009;25.15341
;1.8540;0.10660;0.62558;0.00009;26.33088
;1.8940;0.10900;0.65153;0.00010;27.42322
;1.9300;0.11115;0.67511;0.00010;28.41564
;1.9700;0.11348;0.70023;0.00010;29.47310
;2.0060;0.11557;0.72370;0.00010;30.46108
;2.0460;0.11802;0.74919;0.00011;31.53387
;2.0880;0.12066;0.77669;0.00011;32.69113
;2.1240;0.12281;0.80081;0.00011;33.70662
;2.1680;0.12538;0.82875;0.00012;34.88246
;2.2040;0.12753;0.85260;0.00012;35.88649
;2.2400;0.12974;0.87640;0.00012;36.88807
;2.2760;0.13196;0.90177;0.00013;37.95590
;2.3220;0.13465;0.93098;0.00013;39.18541
;2.3680;0.13734;0.95892;0.00013;40.36131
;2.4040;0.13955;0.98230;0.00013;41.34556
;2.4400;0.14182;1.00710;0.00014;42.38940
;2.4920;0.14487;1.03398;0.00014;43.52089
;2.5460;0.14804;1.06362;0.00015;44.76854
;2.5880;0.15073;1.09131;0.00015;45.93396
;2.6240;0.15294;1.11727;0.00015;47.02658
;2.6600;0.15503;1.14150;0.00016;48.04646
;2.6960;0.15707;1.16462;0.00016;49.01959
;2.7320;0.15922;1.18869;0.00017;50.03269
;2.7680;0.16149;1.21376;0.00017;51.08796
;2.8040;0.16364;1.24012;0.00017;52.19718
;2.8400;0.16574;1.26419;0.00018;53.21059
;2.8760;0.16783;1.28765;0.00019;54.19772
;2.9160;0.17028;1.31379;0.00019;55.29807
;2.9520;0.17255;1.33916;0.00019;56.36616
;2.9880;0.17470;1.36548;0.00019;57.47379
;3.0240;0.17680;1.39122;0.00020;58.55719
;3.0640;0.17919;1.41722;0.00021;59.65158
;3.1000;0.18140;1.44140;0.00020;60.66945
;3.1380;0.18367;1.46667;0.00021;61.73294
;3.1800;0.18612;1.49302;0.00021;62.84216
;3.2340;0.18935;1.52337;0.00022;64.11968
;3.2880;0.19270;1.55495;0.00022;65.44872
;3.3360;0.19557;1.58459;0.00023;66.69621
;3.3860;0.19856;1.61507;0.00023;67.97934
;3.4320;0.20131;1.64322;0.00024;69.16402
;3.4700;0.20364;1.66770;0.00024;70.19440
;3.5100;0.20603;1.69293;0.00025;71.25658
;3.5620;0.20902;1.72325;0.00025;72.53271
;3.6040;0.21154;1.74978;0.00026;73.64932
;3.6400;0.21375;1.77397;0.00026;74.66756
;3.6760;0.21596;1.79847;0.00027;75.69881
;3.7260;0.21889;1.82901;0.00027;76.98402
;3.7680;0.22140;1.85523;0.00028;78.08756
;3.8040;0.22361;1.87907;0.00028;79.09122
;3.8400;0.22582;1.90342;0.00029;80.11623
;3.8860;0.22852;1.93112;0.00029;81.28192
;3.9400;0.23162;1.96277;0.00030;82.61425
;3.9780;0.23402;1.98697;0.00031;83.63261
;4.0140;0.23617;2.01185;0.00032;84.67990
;4.0500;0.23832;2.03585;0.00032;85.69012
;4.1040;0.24149;2.06761;0.00032;87.02679
;4.1500;0.24436;2.09488;0.00033;88.17487
;4.1860;0.24663;2.11982;0.00033;89.22428
;4.2300;0.24920;2.14674;0.00034;90.35766
;4.2820;0.25225;2.17829;0.00034;91.68539
;4.3300;0.25518;2.20735;0.00035;92.90843
;4.3680;0.25745;2.23186;0.00036;93.94008
;4.4160;0.26032;2.26112;0.00037;95.17185
;4.4660;0.26325;2.29134;0.00037;96.44384
;4.5100;0.26606;2.31856;0.00038;97.58940
;4.5540;0.26869;2.34605;0.00038;98.74670
;4.6080;0.27186;2.37676;0.00039;100.03900
;4.6620;0.27509;2.40832;0.00040;101.36739
;4.7160;0.27832;2.44083;0.00040;102.73608
;4.7680;0.28137;2.47236;0.00041;104.06309
;4.8220;0.28460;2.50323;0.00041;105.36257
;4.8680;0.28747;2.53178;0.00042;106.56387
;4.9160;0.29034;2.56087;0.00043;107.78852
;4.9700;0.29357;2.58985;0.00044;109.00840
;5.0220;0.29674;2.62066;0.00044;110.30524
;5.0760;0.29996;2.65233;0.00045;111.63798
;5.1300;0.30307;2.68073;0.00045;112.83331
;5.1840;0.30636;2.71133;0.00046;114.12153
;5.2320;0.30935;2.74094;0.00047;115.36772
;5.2860;0.31246;2.76995;0.00048;116.58891
;5.3400;0.31575;2.79824;0.00048;117.77955
;5.3940;0.31910;2.82932;0.00049;119.08749
;5.4480;0.32227;2.85845;0.00049;120.31365
;5.5020;0.32537;2.88464;0.00050;121.41605
;5.5560;0.32872;2.91280;0.00050;122.60130
;5.6100;0.33189;2.94060;0.00051;123.77159
;5.6720;0.33560;2.96641;0.00052;124.85800
;5.7340;0.33942;2.99210;0.00052;125.93916
;5.8020;0.34349;3.01793;0.00053;127.02634
;5.8740;0.34780;3.04453;0.00053;128.14581
;5.9460;0.35216;3.07374;0.00054;129.37552
;6.0220;0.35664;3.10032;0.00055;130.49429
;6.0820;0.36035;3.12576;0.00055;131.56487
;6.1520;0.36448;3.15194;0.00056;132.66701
;6.2240;0.36884;3.17952;0.00056;133.82767
;6.2900;0.37285;3.20643;0.00057;134.96045
;6.3660;0.37727;3.23177;0.00058;136.02696
;6.4300;0.38116;3.25774;0.00058;137.12024
;6.4940;0.38492;3.28302;0.00059;138.18401
;6.5660;0.38923;3.30900;0.00059;139.27754
;6.6240;0.39282;3.33473;0.00060;140.36069
;6.6960;0.39706;3.36013;0.00060;141.42976
;6.7660;0.40125;3.38769;0.00061;142.58987
;6.8360;0.40549;3.41572;0.00061;143.76961
;6.9080;0.40980;3.44234;0.00062;144.89005
;6.9640;0.41326;3.46750;0.00063;145.94890
;7.0380;0.41763;3.49414;0.00063;147.07033
;7.1020;0.42152;3.51872;0.00063;148.10507
;7.1580;0.42492;3.54356;0.00064;149.15045
;7.2340;0.42941;3.57004;0.00065;150.26509
;7.2900;0.43282;3.59426;0.00065;151.28430
;7.3540;0.43664;3.61900;0.00066;152.32561
;7.4220;0.44065;3.64381;0.00066;153.37024
;7.4900;0.44483;3.67072;0.00067;154.50250
;7.5540;0.44860;3.69645;0.00067;155.58566
;7.6260;0.45291;3.72175;0.00068;156.65054
;7.6940;0.45703;3.74824;0.00069;157.76570
;7.7660;0.46134;3.77342;0.00069;158.82545
;7.8280;0.46516;3.79915;0.00070;159.90822
;7.8940;0.46899;3.82496;0.00070;160.99489
;7.9580;0.47282;3.85091;0.00071;162.08708
;8.0160;0.47634;3.87641;0.00071;163.16032
;8.0880;0.48059;3.90312;0.00072;164.28455
;8.1540;0.48465;3.93006;0.00072;165.41844
;8.2220;0.48866;3.95641;0.00073;166.52765
;8.2920;0.49278;3.98299;0.00074;167.64641
;8.3480;0.49619;4.00704;0.00074;168.65842
;8.4140;0.50014;4.03353;0.00075;169.77367
;8.4800;0.50409;4.05872;0.00076;170.83383
;8.5340;0.50743;4.08268;0.00076;171.84212
;8.6060;0.51168;4.10931;0.00077;172.96333
;8.6700;0.51556;4.13508;0.00077;174.04784
;8.7280;0.51903;4.15997;0.00078;175.09546
;8.8000;0.52334;4.18546;0.00078;176.16838
;8.8660;0.52740;4.21225;0.00079;177.29614
;8.9320;0.53129;4.23824;0.00079;178.38997
;9.0040;0.53559;4.26461;0.00080;179.49982
;9.0580;0.53894;4.28837;0.00081;180.49976
;9.1300;0.54307;4.31625;0.00081;181.67358
;9.1900;0.54672;4.34128;0.00082;182.72701
;9.2480;0.55018;4.36573;0.00082;183.75610
;9.3180;0.55431;4.39182;0.00083;184.85403
;9.3840;0.55837;4.41907;0.00083;186.00101
;9.4440;0.56196;4.44500;0.00084;187.09253
;9.5140;0.56615;4.47128;0.00085;188.19865
;9.5680;0.56949;4.49748;0.00085;189.30167
;9.6280;0.57302;4.52352;0.00086;190.39737
;9.7000;0.57727;4.55030;0.00087;191.52463
;9.7560;0.58080;4.57559;0.00087;192.58925
;9.8240;0.58480;4.60265;0.00088;193.72832
;9.8900;0.58875;4.62736;0.00089;194.76823
;9.9460;0.59216;4.65300;0.00089;195.84749
;10.0140;0.59610;4.67965;0.00090;196.96919
;10.0800;0.60017;4.70589;0.00091;198.07341
;10.1420;0.60387;4.73222;0.00091;199.18187
;10.2120;0.60806;4.75904;0.00092;200.31084
;10.2740;0.61189;4.78574;0.00093;201.43442
;10.3400;0.61571;4.81128;0.00093;202.50960
;10.4040;0.61954;4.83759;0.00094;203.61687
;10.4580;0.62289;4.86157;0.00094;204.62610
;10.5260;0.62689;4.88685;0.00095;205.69022
;10.5840;0.63048;4.91180;0.00095;206.74030
;10.6440;0.63407;4.93650;0.00096;207.77988
;10.7160;0.63825;4.96328;0.00097;208.90730
;10.7760;0.64202;4.98967;0.00097;210.01804
;10.8340;0.64549;5.01457;0.00098;211.06593
;10.9060;0.64973;5.04002;0.00099;212.13742
;10.9600;0.65302;5.06425;0.00099;213.15709
;11.0260;0.65691;5.09014;0.00100;214.24687
;11.0980;0.66121;5.11734;0.00101;215.39171
;11.1560;0.66468;5.14258;0.00101;216.45419
;11.2200;0.66845;5.16682;0.00102;217.47458
;11.2880;0.67263;5.19289;0.00103;218.57158
;11.3460;0.67610;5.21812;0.00103;219.63368
;11.4180;0.68040;5.24391;0.00104;220.71921
;11.4880;0.68471;5.27099;0.00105;221.85909
;11.5580;0.68878;5.29629;0.00105;222.92406
;11.6260;0.69290;5.32306;0.00106;224.05057
;11.6800;0.69619;5.34755;0.00107;225.08127
;11.7520;0.70043;5.37379;0.00108;226.18590
;11.8200;0.70462;5.40170;0.00109;227.36081
;11.8880;0.70857;5.42778;0.00109;228.45840
;11.9600;0.71287;5.45418;0.00110;229.56938
;12.0160;0.71634;5.47865;0.00110;230.59952
;12.0840;0.72028;5.50539;0.00111;231.72488
;12.1520;0.72447;5.53122;0.00111;232.81204
;12.2080;0.72788;5.55643;0.00112;233.87337
;12.2800;0.73212;5.58159;0.00113;234.93243
;12.3480;0.73625;5.60918;0.00114;236.09364
;12.4120;0.74007;5.63527;0.00115;237.19156
;12.4840;0.74438;5.66218;0.00116;238.32452
;12.5520;0.74850;5.69007;0.00116;239.49843
;12.6240;0.75275;5.71489;0.00117;240.54308
;12.6940;0.75699;5.74185;0.00118;241.67764
;12.7540;0.76052;5.76697;0.00119;242.73505
;12.8260;0.76483;5.79371;0.00119;243.86066
;12.8920;0.76883;5.82183;0.00120;245.04402
;12.9600;0.77290;5.84779;0.00121;246.13693
;13.0280;0.77702;5.87462;0.00122;247.26590
;13.0900;0.78073;5.89920;0.00123;248.30061
;13.1580;0.78474;5.92595;0.00123;249.42657
;13.2260;0.78898;5.95286;0.00124;250.55922
;13.2880;0.79263;5.97804;0.00125;251.61917
;13.3620;0.79711;6.00394;0.00125;252.70929
;13.4200;0.80064;6.02885;0.00126;253.75774
;13.4920;0.80483;6.05271;0.00127;254.76212
;13.5560;0.80877;6.07817;0.00127;255.83351
;13.6160;0.81236;6.10285;0.00128;256.87241
;13.6880;0.81660;6.12710;0.00129;257.89304
;13.7520;0.82061;6.15346;0.00130;259.00262
;13.8260;0.82492;6.17861;0.00131;260.06140
;13.8960;0.82910;6.20493;0.00131;261.16891
;13.9520;0.83251;6.22895;0.00132;262.18021
;14.0280;0.83693;6.25383;0.00132;263.22717
;14.1000;0.84142;6.28182;0.00134;264.40536
;14.1720;0.84560;6.30774;0.00134;265.49643
;14.2440;0.85003;6.33357;0.00135;266.58337
;14.3160;0.85427;6.36083;0.00136;267.73102
;14.3900;0.85870;6.38619;0.00137;268.79837
;14.4600;0.86300;6.41365;0.00137;269.95428
;14.5400;0.86778;6.43927;0.00138;271.03232
;14.6120;0.87221;6.46509;0.00139;272.11929
;14.6900;0.87675;6.49038;0.00140;273.18396
;14.7680;0.88148;6.51705;0.00141;274.30627
;14.8520;0.88650;6.54312;0.00142;275.40375
;14.9320;0.89128;6.56752;0.00142;276.43054
;15.0100;0.89601;6.59295;0.00143;277.50107
;15.1020;0.90151;6.61834;0.00144;278.56958
;15.1760;0.90593;6.64294;0.00145;279.60529
;15.2680;0.91149;6.66745;0.00146;280.63693
;15.3480;0.91633;6.69274;0.00146;281.70117
;15.4520;0.92255;6.71802;0.00147;282.76523
;15.5360;0.92751;6.74321;0.00148;283.82559
;15.6240;0.93278;6.76792;0.00149;284.86578
;15.7080;0.93780;6.79254;0.00150;285.90201
;15.8040;0.94360;6.81778;0.00151;286.96420
;15.8920;0.94880;6.84276;0.00151;288.01581
;15.9800;0.95412;6.86788;0.00153;289.07309
;16.0660;0.95932;6.89291;0.00153;290.12656
;16.1680;0.96548;6.91763;0.00154;291.16684
;16.2960;0.97307;6.94178;0.00155;292.18362
;16.3780;0.97804;6.96660;0.00156;293.22833
;16.4780;0.98402;6.99186;0.00157;294.29144
;16.5640;0.98916;7.01741;0.00158;295.36673
;16.6660;0.99526;7.04204;0.00159;296.40359
;16.7660;1.00123;7.06761;0.00160;297.47983
;16.8680;1.00745;7.09183;0.00160;298.49908
;16.9700;1.01349;7.11654;0.00161;299.53918
;17.0580;1.01893;7.14184;0.00162;300.60410
;17.1560;1.02467;7.16654;0.00163;301.64355
;17.2400;1.02981;7.19219;0.00164;302.72318
;17.3520;1.03639;7.21697;0.00165;303.76651
;17.4360;1.04153;7.24256;0.00166;304.84323
;17.5400;1.04775;7.26763;0.00167;305.89856
;17.6360;1.05349;7.29230;0.00168;306.93683
;17.7540;1.06067;7.31651;0.00169;307.95590
;17.8700;1.06760;7.34133;0.00170;309.00095
;17.9520;1.07256;7.36587;0.00171;310.03372
;18.0600;1.07896;7.39087;0.00172;311.08591
;18.1560;1.08476;7.41546;0.00173;312.12082
;18.2660;1.09146;7.43997;0.00174;313.15237
;18.3680;1.09738;7.46463;0.00175;314.19067
;18.4600;1.10300;7.48944;0.00177;315.23471
;18.5700;1.10951;7.51366;0.00177;316.25436
;18.6600;1.11495;7.53799;0.00179;317.27841
;18.7680;1.12147;7.56218;0.00180;318.29654
;18.8740;1.12775;7.58721;0.00181;319.34995
;18.9780;1.13415;7.61183;0.00182;320.38620
;19.0940;1.14102;7.63581;0.00184;321.39542
;19.1880;1.14664;7.66020;0.00185;322.42230
;19.2980;1.15322;7.68401;0.00186;323.42438
;19.4120;1.15998;7.70843;0.00187;324.45224
;19.5140;1.16619;7.73290;0.00189;325.48206
;19.6260;1.17289;7.75718;0.00190;326.50406
;19.7320;1.17923;7.78111;0.00191;327.51123
;19.8420;1.18598;7.80492;0.00192;328.51358
;19.9560;1.19268;7.82898;0.00194;329.52625
;20.0780;1.19998;7.85351;0.00195;330.55856
;20.1920;1.20691;7.87818;0.00197;331.59702
;20.3340;1.21528;7.90211;0.00198;332.60419
;20.4600;1.22287;7.92643;0.00200;333.62790
;20.5660;1.22939;7.95102;0.00201;334.66309
;20.6960;1.23722;7.97471;0.00202;335.66006
;20.8140;1.24422;7.99919;0.00204;336.69034
;20.9200;1.25068;8.02285;0.00206;337.68631
;21.0540;1.25875;8.04728;0.00207;338.71439
;21.1980;1.26724;8.07164;0.00209;339.73984
;21.3320;1.27531;8.09593;0.00211;340.76236
;21.4760;1.28386;8.12018;0.00213;341.78290
;21.5940;1.29109;8.14428;0.00215;342.79742
;21.7320;1.29935;8.16795;0.00217;343.79382
;21.9320;1.31136;8.19203;0.00219;344.80728
;22.0860;1.32057;8.21629;0.00221;345.82819
;22.2540;1.33062;8.24018;0.00223;346.83405
;22.3900;1.33869;8.26361;0.00225;347.81982
;22.5400;1.34777;8.28741;0.00227;348.82196
;22.7100;1.35794;8.31113;0.00229;349.82019
;22.8660;1.36733;8.33541;0.00232;350.84229
;23.0260;1.37695;8.35968;0.00234;351.86356
;23.1920;1.38682;8.38354;0.00237;352.86801
;23.3960;1.39913;8.40728;0.00240;353.86700
;23.5840;1.41037;8.43086;0.00243;354.85977
;23.7860;1.42257;8.45466;0.00246;355.86151
;24.0040;1.43561;8.47819;0.00249;356.85172
;24.1940;1.44709;8.50190;0.00251;357.84964
;24.4580;1.46281;8.52579;0.00255;358.85529
;24.7020;1.47752;8.54943;0.00258;359.85049
;24.9320;1.49133;8.57346;0.00262;360.86200
;25.2020;1.50753;8.59711;0.00265;361.85721
;25.5200;1.52655;8.62044;0.00270;362.83902
;25.8420;1.54586;8.64400;0.00274;363.83066
;26.1200;1.56266;8.66715;0.00278;364.80527
;26.4640;1.58329;8.69044;0.00284;365.78558
;26.8780;1.60798;8.71377;0.00290;366.76758
;27.3460;1.63620;8.73668;0.00299;367.73184
;27.8300;1.66520;8.75846;0.00307;368.64841
;28.2180;1.68857;8.77843;0.00316;369.48920
;28.6940;1.71703;8.79570;0.00327;370.21579
;29.2280;1.74908;8.81514;0.00344;371.03421
;29.8600;1.78693;8.83043;0.00369;371.67798
;30.5680;1.82938;8.84025;0.00395;372.09122
;31.3300;1.87530;8.84557;0.00430;372.31506
;32.1080;1.92175;8.84127;0.00465;372.13416
;32.7520;1.96050;8.82981;0.00492;371.65173
;33.5140;2.00612;8.83548;0.00526;371.89029
;34.1940;2.04695;8.83910;0.00568;372.04254
;34.9780;2.09407;8.85075;0.00624;372.53302
;35.6640;2.13532;8.85161;0.00674;372.56946
;36.3500;2.17646;8.85824;0.00736;372.84814
;36.9820;2.21424;8.86383;0.00801;373.08380
;37.7580;2.26088;8.87147;0.00881;373.40515
;38.6160;2.31236;8.87114;0.00977;373.39148
;39.2500;2.35032;8.87515;0.01052;373.56021
;39.8480;2.38626;8.88447;0.01111;373.95258
;40.6420;2.43379;8.89045;0.01166;374.20392
;41.3540;2.47660;8.89569;0.01201;374.42471
;42.1900;2.52664;8.89784;0.01231;374.51511
;42.8280;2.56509;8.90907;0.01248;374.98795
;43.4840;2.60449;8.91942;0.01264;375.42328
;44.2380;2.64963;8.91833;0.01282;375.37747
;44.9740;2.69376;8.92281;0.01299;375.56598
;45.6740;2.73579;8.92155;0.01317;375.51321
;46.4540;2.78278;8.92086;0.01339;375.48401
;47.2480;2.83025;8.91666;0.01368;375.30707
;48.0380;2.87773;8.90887;0.01413;374.97943
;48.7120;2.91809;8.90610;0.01468;374.86298
;49.5100;2.96586;8.92055;0.01526;375.47107
;50.1020;3.00161;8.94084;0.01554;376.32492
;50.7380;3.03958;8.95183;0.01574;376.78754
;51.3360;3.07563;8.96708;0.01587;377.42947
;51.9640;3.11324;8.98110;0.01597;378.01941
;52.5440;3.14810;8.99533;0.01605;378.61838
;53.1680;3.18541;9.01019;0.01613;379.24417
;53.7620;3.22122;9.02591;0.01621;379.90555
;54.3960;3.25907;9.03870;0.01629;380.44379
;54.9620;3.29315;9.05087;0.01637;380.95642
;55.6680;3.33554;9.06883;0.01647;381.71216
;56.3540;3.37667;9.08142;0.01658;382.24210
;56.9280;3.41111;9.09401;0.01668;382.77222
;57.6740;3.45577;9.10750;0.01681;383.34000
;58.4080;3.49984;9.12167;0.01695;383.93616
;59.0700;3.53954;9.13603;0.01707;384.54080
;59.8180;3.58444;9.15114;0.01721;385.17661
;60.5580;3.62886;9.16665;0.01735;385.82962
;61.2380;3.66982;9.17730;0.01749;386.27783
;61.9580;3.71293;9.19230;0.01765;386.90909
;62.7440;3.76004;9.19762;0.01788;387.13324
;63.4480;3.80213;9.19810;0.01813;387.15326
;64.0280;3.83711;9.18240;0.01832;386.49225
;64.6360;3.87346;9.17262;0.01862;386.08066
;65.0320;3.89720;9.14935;0.01891;385.10147
;65.3640;3.91717;9.12628;0.01927;384.13010
;65.8620;3.94706;9.10660;0.01995;383.30212
;66.5580;3.98880;9.11287;0.02086;383.56564
;67.1260;4.02294;9.12625;0.02139;384.12918
;67.6820;4.05636;9.14646;0.02179;384.97989
;68.0780;4.08009;9.16898;0.02201;385.92749
;68.5620;4.10921;9.18833;0.02221;386.74210
;69.2620;4.15118;9.19054;0.02244;386.83487
;69.7180;4.17845;9.17937;0.02253;386.36496
;70.2600;4.21103;9.17270;0.02265;386.08411
;70.6840;4.23638;9.15256;0.02274;385.23630
;71.2360;4.26951;9.13751;0.02282;384.60300
;71.6080;4.29181;9.12328;0.02287;384.00403
;71.8100;4.30389;9.14666;0.02290;384.98795
;72.0320;4.31740;9.17045;0.02293;385.98923
;72.2260;4.32894;9.19404;0.02296;386.98251
;72.4680;4.34335;9.21728;0.02301;387.96039
;72.6960;4.35716;9.24107;0.02306;388.96191
;72.9620;4.37312;9.26431;0.02312;389.94003
;73.2180;4.38855;9.28742;0.02318;390.91272
;73.5280;4.40702;9.31077;0.02325;391.89557
;73.8900;4.42879;9.33403;0.02334;392.87479
;74.3160;4.45438;9.35654;0.02345;393.82217
;74.8940;4.48893;9.37586;0.02359;394.63538
;75.3480;4.51620;9.39556;0.02371;395.46432
;75.8720;4.54777;9.41471;0.02387;396.27029
;76.3880;4.57880;9.43293;0.02403;397.03741
;76.8960;4.60917;9.45115;0.02419;397.80432
;77.4280;4.64110;9.47104;0.02437;398.64163
;78.0520;4.67847;9.49173;0.02460;399.51208
;78.5800;4.71016;9.51123;0.02479;400.33319
;79.1120;4.74208;9.52981;0.02500;401.11530
;79.5160;4.76642;9.54838;0.02516;401.89670
;80.0620;4.79912;9.56705;0.02538;402.68271
;80.5840;4.83045;9.58722;0.02560;403.53137
;81.1920;4.86692;9.60743;0.02585;404.38235
;81.7500;4.90035;9.62833;0.02608;405.26178
;82.2600;4.93096;9.64525;0.02630;405.97412
;82.8020;4.96354;9.66675;0.02653;406.87906
;83.3320;4.99529;9.68464;0.02677;407.63184
;83.8180;5.02447;9.70090;0.02698;408.31656
;84.3900;5.05885;9.72116;0.02723;409.16925
;84.9020;5.08952;9.73915;0.02745;409.92618
;85.4940;5.12498;9.75941;0.02771;410.77914
;86.1060;5.16169;9.77953;0.02799;411.62582
;86.6320;5.19338;9.79774;0.02822;412.39233
;87.1480;5.22429;9.81338;0.02845;413.05051
;87.7060;5.25783;9.83484;0.02870;413.95401
;88.3220;5.29466;9.85346;0.02898;414.73758
;88.9400;5.33173;9.87431;0.02926;415.61520
;89.5540;5.36862;9.89258;0.02953;416.38437
;90.1040;5.40156;9.91143;0.02978;417.17773
;90.6400;5.43379;9.92852;0.03003;417.89709
;91.1500;5.46452;9.94503;0.03026;418.59210
;91.6720;5.49567;9.96172;0.03050;419.29456
;92.3100;5.53400;9.98044;0.03079;420.08231
;92.8900;5.56879;9.99973;0.03105;420.89426
;93.4320;5.60132;10.01757;0.03129;421.64511
;93.9640;5.63337;10.03543;0.03154;422.39713
;94.4700;5.66362;10.05008;0.03178;423.01376
;95.0920;5.70087;10.06677;0.03206;423.71603
;95.7080;5.73794;10.08735;0.03234;424.58237
;96.3580;5.77686;10.10367;0.03264;425.26938
;96.9220;5.81070;10.12337;0.03291;426.09833
;97.5760;5.84992;10.14094;0.03321;426.83783
;98.1060;5.88173;10.15644;0.03345;427.49033
;98.6580;5.91497;10.17401;0.03371;428.22992
;99.3280;5.95503;10.19140;0.03402;428.96173
;99.9620;5.99312;10.20781;0.03432;429.65253
;100.5480;6.02822;10.22558;0.03459;430.40060
;101.0740;6.05984;10.24001;0.03483;431.00781
;101.5920;6.09093;10.25377;0.03508;431.58698
;102.2280;6.12902;10.27139;0.03538;432.32855
;102.7700;6.16155;10.28539;0.03564;432.91791
;103.3440;6.19598;10.30148;0.03591;433.59503
;103.9920;6.23491;10.31715;0.03621;434.25473
;104.5220;6.26666;10.33232;0.03647;434.89322
;105.1000;6.30145;10.34997;0.03674;435.63593
;105.7300;6.33912;10.36349;0.03704;436.20517
;106.2580;6.37081;10.37628;0.03729;436.74347
;106.8980;6.40919;10.39401;0.03760;437.48962
;107.5140;6.44632;10.40987;0.03790;438.15741
;108.2180;6.48848;10.42837;0.03823;438.93588
;108.8900;6.52877;10.44469;0.03856;439.62296
;109.4360;6.56166;10.46077;0.03882;440.29987
;110.1140;6.60225;10.47601;0.03916;440.94122
;110.8020;6.64345;10.49126;0.03948;441.58322
;111.4460;6.68207;10.50675;0.03980;442.23489
;112.0600;6.71902;10.52398;0.04009;442.96033
;112.6860;6.75651;10.53687;0.04040;443.50296
;113.3640;6.79717;10.55199;0.04074;444.13940
;113.9720;6.83370;10.56741;0.04103;444.78812
;114.7360;6.87950;10.58407;0.04141;445.48938
;115.3520;6.91651;10.60043;0.04171;446.17828
;116.0360;6.95764;10.61371;0.04204;446.73721
;116.6580;6.99489;10.62745;0.04235;447.31555
;117.3700;7.03752;10.64304;0.04270;447.97141
;118.1280;7.08308;10.66073;0.04307;448.71613
;118.9220;7.13061;10.67673;0.04346;449.38956
;119.5700;7.16960;10.69329;0.04379;450.08646
;120.1820;7.20625;10.70455;0.04409;450.56055
;120.7600;7.24104;10.71606;0.04437;451.04504
;121.4320;7.28134;10.73169;0.04471;451.70309
;122.1100;7.32194;10.74364;0.04504;452.20584
;122.8200;7.36457;10.75978;0.04540;452.88531
;123.3700;7.39769;10.77248;0.04567;453.41983
;124.0220;7.43668;10.78377;0.04600;453.89484
;124.7280;7.47907;10.79662;0.04635;454.43607
;125.4600;7.52301;10.81226;0.04672;455.09409
;126.0980;7.56122;10.82389;0.04704;455.58365
;126.7660;7.60128;10.83596;0.04737;456.09161
;127.3560;7.63679;10.85001;0.04767;456.68304
;128.0120;7.67607;10.85972;0.04799;457.09180
;128.6920;7.71685;10.87389;0.04834;457.68814
;129.3860;7.75858;10.88758;0.04868;458.26428
;130.0720;7.79960;10.90036;0.04903;458.80237
;130.8380;7.84570;10.91505;0.04942;459.42078
;131.5420;7.88797;10.92636;0.04978;459.89658
;132.3460;7.93604;10.93960;0.05036;460.45389
;133.1200;7.98255;10.95535;0.05114;461.11673
;133.8240;8.02489;10.96912;0.05184;461.69656
;134.4400;8.06172;10.97571;0.05246;461.97385
;135.1120;8.10207;10.98769;0.05313;462.47806
;135.8160;8.14435;10.99974;0.05384;462.98544
;136.5840;8.19050;11.01409;0.05461;463.58920
;137.2820;8.23236;11.02833;0.05530;464.18869
;137.9860;8.27457;11.03969;0.05601;464.66666
;138.5960;8.31122;11.04762;0.05662;465.00067
;139.1920;8.34691;11.06151;0.05721;465.58508
;140.0040;8.39552;11.06991;0.05802;465.93866
;140.7640;8.44120;11.08389;0.05878;466.52710
;141.4960;8.48520;11.09639;0.05952;467.05331
;142.1440;8.52413;11.10554;0.06017;467.43854
;142.8660;8.56736;11.11668;0.06089;467.90729
;143.7040;8.61764;11.12974;0.06172;468.45715
;144.5200;8.66655;11.13987;0.06254;468.88351
;145.1880;8.70655;11.15037;0.06321;469.32538
;145.8940;8.74900;11.16119;0.06391;469.78067
;146.6680;8.79545;11.17330;0.06469;470.29047
;147.4820;8.84424;11.18432;0.06550;470.75436
;148.2580;8.89082;11.19815;0.06628;471.33646
;149.0480;8.93817;11.20466;0.06707;471.61066
;149.6200;8.97261;11.21530;0.06764;472.05844
;150.5080;9.02600;11.22805;0.06853;472.59512
;151.2220;9.06869;11.23875;0.06924;473.04532
;152.0620;9.11915;11.24833;0.07008;473.44867
;152.7900;9.16274;11.25908;0.07081;473.90088
;153.5660;9.20932;11.26720;0.07159;474.24271
;154.3140;9.25422;11.27867;0.07233;474.72543
;155.0320;9.29739;11.28750;0.07305;475.09705
;155.8200;9.34450;11.29692;0.07384;475.49384
;156.5740;9.38988;11.30606;0.07459;475.87854
;157.3280;9.43508;11.31530;0.07535;476.26755
;158.1640;9.48530;11.32517;0.07619;476.68262
;158.9560;9.53266;11.33424;0.07697;477.06467
;159.7420;9.58001;11.34593;0.07776;477.55661
;160.5260;9.62695;11.35357;0.07855;477.87799
;161.3780;9.67801;11.36356;0.07940;478.29852
;162.1900;9.72679;11.37456;0.08021;478.76166
;163.0340;9.77744;11.38456;0.08105;479.18246
;163.8320;9.82521;11.39089;0.08185;479.44904
;164.5320;9.86724;11.39847;0.08255;479.76807
;165.2920;9.91304;11.41034;0.08331;480.26773
;166.0980;9.96123;11.41716;0.08412;480.55469
;166.8540;10.00673;11.42711;0.08488;480.97363
;167.5720;10.04978;11.43683;0.08559;481.38284
;168.3420;10.09587;11.44090;0.08636;481.55411
;169.1620;10.14502;11.45177;0.08718;482.01141
;169.9860;10.19453;11.46045;0.08801;482.37671
;170.7820;10.24224;11.46625;0.08880;482.62079
;171.4900;10.28481;11.47401;0.08951;482.94751
;172.2320;10.32929;11.48210;0.09025;483.28812
;173.1000;10.38137;11.49146;0.09112;483.68192
;173.9020;10.42944;11.49942;0.09192;484.01700
;174.6860;10.47655;11.50840;0.09271;484.39499
;175.3920;10.51894;11.51465;0.09341;484.65814
;176.2080;10.56779;11.52154;0.09423;484.94818
;177.0420;10.61778;11.52790;0.09506;485.21600
;177.8260;10.66495;11.53807;0.09585;485.64386
;178.5200;10.70668;11.54464;0.09654;485.92041
;179.3060;10.75368;11.54890;0.09732;486.09955
;180.1460;10.80408;11.55841;0.09816;486.50009
;180.9600;10.85299;11.56623;0.09898;486.82898
;181.8080;10.90387;11.57355;0.09983;487.13739
;182.6440;10.95403;11.58027;0.10066;487.42029
;183.4740;11.00378;11.58741;0.10149;487.72049
;184.3260;11.05490;11.59614;0.10234;488.08792
;185.1200;11.10267;11.60286;0.10314;488.37097
;185.8280;11.14512;11.60988;0.10385;488.66620
;186.6220;11.19259;11.61404;0.10464;488.84143
;187.4580;11.24276;11.62196;0.10548;489.17487
;188.3580;11.29675;11.62804;0.10638;489.43076
;189.1280;11.34320;11.63618;0.10715;489.77359
;189.9380;11.39169;11.64162;0.10796;490.00235
;190.7500;11.44048;11.64886;0.10877;490.30707
;191.6480;11.49423;11.65300;0.10967;490.48145
;192.4740;11.54386;11.66166;0.11049;490.84583
;193.2320;11.58924;11.66519;0.11125;490.99460
;194.1040;11.64155;11.67151;0.11212;491.26044
;194.8160;11.68436;11.67628;0.11284;491.46124
;195.6480;11.73411;11.68300;0.11367;491.74429
;196.4460;11.78224;11.69078;0.11447;492.07135
;197.2880;11.83270;11.69612;0.11531;492.29636
;198.0840;11.88041;11.70083;0.11610;492.49451
;198.9040;11.92962;11.70938;0.11692;492.85443
;199.6780;11.97602;11.71165;0.11770;492.94980
;200.4700;12.02361;11.72008;0.11849;493.30484
;201.2420;12.06982;11.72285;0.11926;493.42157
;202.0800;12.12011;11.72930;0.12010;493.69308
;202.8860;12.16848;11.73503;0.12090;493.93387
;203.7280;12.21912;11.74166;0.12175;494.21317
;204.5700;12.26958;11.74678;0.12259;494.42874
;205.4540;12.32267;11.75211;0.12347;494.65286
;206.1900;12.36680;11.75841;0.12421;494.91800
;207.0460;12.41822;11.76383;0.12507;495.14645
;207.8460;12.46605;11.76696;0.12586;495.27820
;208.6500;12.51436;11.77338;0.12667;495.54834
;209.4320;12.56117;11.77681;0.12745;495.69278
;210.2400;12.60972;11.78255;0.12826;495.93423
;211.0640;12.65929;11.78979;0.12908;496.23886
;211.8300;12.70515;11.79365;0.12985;496.40155
;212.6060;12.75184;11.79960;0.13063;496.65167
;213.5040;12.80565;11.80470;0.13152;496.86639
;214.2920;12.85289;11.80672;0.13231;496.95172
;215.0540;12.89869;11.81350;0.13307;497.23682
;215.8680;12.94747;11.81558;0.13389;497.32425
;216.7680;13.00140;11.82174;0.13479;497.58374
;217.6320;13.05324;11.82548;0.13565;497.74121
;218.4800;13.10406;11.82994;0.13650;497.92883
;219.2440;13.15010;11.83558;0.13727;498.16623
;220.1040;13.20164;11.84188;0.13812;498.43121
;220.9080;13.24977;11.84468;0.13893;498.54910
;221.6920;13.29688;11.85144;0.13971;498.83368
;222.4860;13.34448;11.85228;0.14050;498.86905
;223.3320;13.39530;11.85734;0.14135;499.08218
;224.1940;13.44696;11.86095;0.14221;499.23398
;224.9640;13.49323;11.86647;0.14298;499.46634
;225.7620;13.54100;11.87000;0.14378;499.61490
;226.5240;13.58686;11.87446;0.14454;499.80273
;227.4240;13.64085;11.87829;0.14544;499.96396
;228.3060;13.69383;11.88358;0.14633;500.18677
;229.1700;13.74560;11.88770;0.14719;500.35995
;229.9340;13.79134;11.88978;0.14795;500.44775
;230.7240;13.83888;11.89578;0.14874;500.70004
;231.4820;13.88426;11.89785;0.14950;500.78726
;232.3720;13.93759;11.90083;0.15039;500.91260
;233.1660;13.98530;11.90802;0.15119;501.21512
;234.0080;14.03588;11.91102;0.15203;501.34171
;234.8260;14.08491;11.91360;0.15285;501.45007
;235.6880;14.13663;11.91763;0.15371;501.61990
;236.4820;14.18434;11.92378;0.15450;501.87845
;237.3180;14.23450;11.92749;0.15534;502.03482
;238.1460;14.28413;11.92929;0.15617;502.11047
;239.0460;14.33818;11.93311;0.15707;502.27136
;239.8740;14.38780;11.93601;0.15789;502.39362
;240.6540;14.43468;11.94206;0.15867;502.64807
;241.4760;14.48400;11.94357;0.15950;502.71164
;242.3760;14.53794;11.94883;0.16040;502.93292
;243.2320;14.58929;11.95182;0.16125;503.05899
;244.0340;14.63730;11.95460;0.16205;503.17593
;244.8700;14.68753;11.95918;0.16289;503.36868
;245.7380;14.73967;11.96196;0.16376;503.48553
;246.6380;14.79359;11.96522;0.16466;503.62308
;247.4460;14.84220;11.97033;0.16547;503.83789
;248.2160;14.88836;11.97199;0.16624;503.90771
;249.0560;14.93876;11.97450;0.16708;504.01364
;249.8960;14.98911;11.98007;0.16792;504.24774
;250.7420;15.03987;11.98444;0.16876;504.43192
;251.5060;15.08567;11.98448;0.16952;504.43347
;252.3020;15.13350;11.98959;0.17032;504.64874
;253.1440;15.18402;11.99224;0.17116;504.76025
;254.0220;15.23669;11.99529;0.17204;504.88876
;254.8160;15.28429;11.99857;0.17283;505.02661
;255.6960;15.33714;12.00200;0.17372;505.17090
;256.5560;15.38874;12.00464;0.17458;505.28192
;257.4100;15.43998;12.00761;0.17543;505.40720
;258.2380;15.48966;12.01222;0.17626;505.60104
;259.0080;15.53582;12.01306;0.17703;505.63644
;259.8480;15.58616;12.01611;0.17787;505.76505
;260.7080;15.63776;12.01932;0.17873;505.90012
;261.5060;15.68571;12.02323;0.17953;506.06448
;262.3480;15.73624;12.02499;0.18037;506.13876
;263.1880;15.78658;12.02737;0.18121;506.23874
;264.0880;15.84069;12.03071;0.18211;506.37927
;264.9740;15.89390;12.03259;0.18299;506.45865
;265.8300;15.94520;12.03624;0.18385;506.61209
;266.6800;15.99614;12.03867;0.18470;506.71463
;267.5660;16.04935;12.04224;0.18559;506.86459
;268.4260;16.10089;12.04444;0.18644;506.95749
;269.3240;16.15494;12.04840;0.18735;507.12390
;270.1280;16.20307;12.04877;0.18815;507.13953
;270.9800;16.25419;12.05238;0.18900;507.29163
;271.8800;16.30806;12.05394;0.18990;507.35696
;272.6640;16.35524;12.05886;0.19068;507.56409
;273.5000;16.40546;12.06097;0.19152;507.65292
;274.3320;16.45526;12.06215;0.19235;507.70279
;275.1920;16.50680;12.06384;0.19321;507.77390
;276.0560;16.55864;12.06614;0.19407;507.87085
;276.9040;16.60958;12.06969;0.19492;508.01993
;277.7260;16.65897;12.07336;0.19575;508.17465
;278.5660;16.70943;12.07472;0.19659;508.23190
;279.4560;16.76276;12.07820;0.19748;508.37811
;280.3080;16.81394;12.08101;0.19833;508.49649
;281.0940;16.86100;12.08033;0.19911;508.46780
;281.9620;16.91307;12.08319;0.19998;508.58829
;282.7620;16.96108;12.08625;0.20078;508.71725
;283.6360;17.01358;12.08922;0.20166;508.84219
;284.4080;17.05985;12.08925;0.20243;508.84351
;285.1900;17.10679;12.09240;0.20321;508.97589
;286.0900;17.16078;12.09335;0.20411;509.01605
;286.9420;17.21190;12.09623;0.20496;509.13727
;287.7620;17.26111;12.09872;0.20578;509.24203
;288.5580;17.30882;12.09803;0.20658;509.21298
;289.3880;17.35868;12.10150;0.20741;509.35898
;290.2340;17.40944;12.10456;0.20825;509.48788
;291.0940;17.46104;12.10688;0.20911;509.58551
;291.9940;17.51515;12.10781;0.21002;509.62476
;292.8300;17.56532;12.11018;0.21085;509.72449
;293.6340;17.61339;12.10932;0.21165;509.68814
;294.4740;17.66379;12.11073;0.21249;509.74759
;295.2780;17.71210;12.11405;0.21330;509.88736
;296.1140;17.76220;12.11441;0.21413;509.90228
;296.9620;17.81302;12.11558;0.21498;509.95178
;297.8420;17.86588;12.11772;0.21586;510.04181
;298.6640;17.91514;12.11908;0.21668;510.09891
;299.5400;17.96776;12.12152;0.21756;510.20175
;300.3860;18.01858;12.12261;0.21841;510.24765
;301.2680;18.07137;12.12377;0.21929;510.29623
;302.1320;18.12321;12.12556;0.22015;510.37167
;302.9380;18.17170;12.12904;0.22096;510.51816
;303.7720;18.22174;12.12993;0.22179;510.55557
;304.6420;18.27394;12.13171;0.22266;510.63074
;305.4840;18.32434;12.13156;0.22350;510.62405
;306.2300;18.36918;12.13369;0.22425;510.71399
;307.0760;18.42001;12.13341;0.22510;510.70193
;307.9420;18.47190;12.13418;0.22596;510.73438
;308.7620;18.52111;12.13570;0.22678;510.79840
;309.6140;18.57223;12.13692;0.22763;510.85004
;310.4360;18.62162;12.13874;0.22846;510.92645
;311.3300;18.67519;12.14012;0.22935;510.98434
;312.1420;18.72392;12.14267;0.23016;511.09177
;313.0320;18.77737;12.14442;0.23105;511.16550
;313.9060;18.82980;12.14487;0.23193;511.18457
;314.7820;18.88236;12.14573;0.23280;511.22067
;315.6280;18.93306;12.14546;0.23365;511.20911
;316.4880;18.98466;12.14760;0.23451;511.29941
;317.3000;19.03327;12.14564;0.23532;511.21674
;318.0580;19.07889;12.14801;0.23608;511.31647
;318.9580;19.13282;12.14944;0.23698;511.37698
;319.8580;19.18681;12.15038;0.23788;511.41635
;320.6760;19.23601;12.15312;0.23870;511.53162
;321.5460;19.28833;12.15212;0.23957;511.48969
;322.3720;19.33777;12.15169;0.24039;511.47144
;323.2720;19.39176;12.15322;0.24129;511.53595
;324.1280;19.44307;12.15472;0.24215;511.59900
;324.9880;19.49466;12.15474;0.24301;511.59985
;325.8840;19.54853;12.15519;0.24391;511.61890
;326.7840;19.60240;12.15709;0.24480;511.69894
;327.6460;19.65418;12.15846;0.24567;511.75626
;328.5080;19.70596;12.15909;0.24653;511.78305
;329.3080;19.75385;12.15838;0.24733;511.75305
;330.1760;19.80587;12.15813;0.24819;511.74255
;331.0420;19.85788;12.15840;0.24906;511.75403
;331.8020;19.90356;12.16121;0.24982;511.87225
;332.7020;19.95755;12.16158;0.25072;511.88788
;333.5460;20.00826;12.16031;0.25157;511.83423
;334.3560;20.05674;12.16020;0.25238;511.82986
;335.2560;20.11073;12.16181;0.25328;511.89764
;336.1380;20.16371;12.16247;0.25416;511.92532
;337.0160;20.21638;12.16217;0.25504;511.91278
;337.9160;20.27037;12.16367;0.25594;511.97562
;338.7780;20.32209;12.16415;0.25680;511.99609
;339.6300;20.37327;12.16373;0.25765;511.97812
;340.4860;20.42457;12.16452;0.25851;512.01166
;341.3760;20.47802;12.16585;0.25940;512.06763
;342.2460;20.53028;12.16542;0.26027;512.04932
;343.0600;20.57900;12.16385;0.26108;511.98337
;343.8880;20.62869;12.16300;0.26191;511.94742
;344.6840;20.67646;12.16557;0.26270;512.05554
;345.5660;20.72931;12.16445;0.26359;512.00854
;346.3860;20.77852;12.16422;0.26441;511.99902
;347.2200;20.82851;12.16239;0.26524;511.92181
;348.0920;20.88076;12.16363;0.26611;511.97409
;348.9920;20.93487;12.16446;0.26701;512.00903
;349.8200;20.98456;12.16391;0.26784;511.98581
;350.5920;21.03095;12.16571;0.26861;512.06158
;351.4920;21.08500;12.16500;0.26951;512.03174
;352.3920;21.13887;12.16514;0.27041;512.03760
;353.2920;21.19286;12.16388;0.27131;511.98480
;354.0760;21.24004;12.16548;0.27210;512.05194
;354.8840;21.28835;12.16260;0.27290;511.93066
;355.7520;21.34048;12.16300;0.27377;511.94751
;356.5840;21.39035;12.16164;0.27460;511.89020
;357.4040;21.43967;12.16275;0.27542;511.93719
;358.2720;21.49175;12.16194;0.27629;511.90286
;359.1460;21.54407;12.16133;0.27716;511.87711
;359.9960;21.59513;12.16219;0.27802;511.91330
;360.8860;21.64858;12.16121;0.27891;511.87201
;361.6640;21.69522;12.15924;0.27968;511.78937
;362.5600;21.74903;12.15949;0.28058;511.79977
;363.4460;21.80218;12.15716;0.28147;511.70184
;364.2480;21.85025;12.15620;0.28227;511.66135
;365.0780;21.90011;12.15791;0.28310;511.73312
;365.9200;21.95064;12.15641;0.28394;511.67010
;366.8200;22.00451;12.15631;0.28484;511.66586
;367.7200;22.05861;12.15346;0.28574;511.54584
;368.5360;22.10764;12.15459;0.28656;511.59360
;369.4060;22.15978;12.15307;0.28743;511.52960
;370.3060;22.21365;12.15107;0.28832;511.44531
;371.2060;22.26758;12.14877;0.28922;511.34842
;372.0920;22.32091;12.14659;0.29011;511.25693
;372.9020;22.36946;12.14693;0.29092;511.27136
;373.7620;22.42112;12.14542;0.29178;511.20767
;374.5740;22.46985;12.14252;0.29259;511.08560
;375.4040;22.51959;12.14064;0.29342;511.00623
;376.1960;22.56724;12.14088;0.29422;511.01654
;377.0960;22.62111;12.13899;0.29512;510.93692
;377.9960;22.67510;12.13653;0.29602;510.83347
;378.8360;22.72557;12.13560;0.29686;510.79428
;379.6940;22.77711;12.13373;0.29772;510.71555
;380.5120;22.82619;12.13143;0.29853;510.61896
;381.4080;22.87988;12.12836;0.29943;510.48935
;382.2640;22.93118;12.12506;0.30028;510.35059
;383.1300;22.98320;12.12250;0.30115;510.24271
;383.9380;23.03163;12.11895;0.30196;510.09363
;384.8220;23.08460;12.11612;0.30284;509.97427
;385.6420;23.13381;12.11248;0.30366;509.82104
;386.5060;23.18571;12.10788;0.30453;509.62756
;387.3580;23.23689;12.10616;0.30538;509.55496
;388.2580;23.29082;12.10166;0.30628;509.36551
;389.1340;23.34331;12.09670;0.30715;509.15704
;389.9540;23.39264;12.09303;0.30797;509.00235
;390.8220;23.44471;12.08854;0.30884;508.81335
;391.5840;23.49045;12.08176;0.30960;508.52826
;392.4600;23.54301;12.07554;0.31048;508.26611
;393.3160;23.59431;12.06770;0.31134;507.93634
;394.1520;23.64453;12.06011;0.31217;507.61682
;395.0000;23.69535;12.05257;0.31302;507.29968
;395.8200;23.74456;12.04228;0.31384;506.86652
;396.6880;23.79663;12.03114;0.31471;506.39731
;397.4760;23.84387;12.01819;0.31549;505.85233
;398.2680;23.89152;12.00715;0.31629;505.38788
;399.0640;23.93924;11.99137;0.31708;504.72351
;399.7880;23.98264;11.97500;0.31781;504.03473
;400.4780;24.02402;11.95930;0.31850;503.37357
;401.1260;24.06288;11.94388;0.31914;502.72449
;401.6600;24.09505;11.92887;0.31968;502.09290
;402.3260;24.13492;11.90868;0.32035;501.24323
;402.8900;24.16877;11.88908;0.32091;500.41812
;403.5460;24.20817;11.86869;0.32157;499.55991
;404.0860;24.24045;11.84771;0.32210;498.67661
;404.6100;24.27190;11.82644;0.32263;497.78137
;405.1660;24.30532;11.80532;0.32319;496.89273
;405.6660;24.33528;11.78336;0.32368;495.96838
;406.1720;24.36565;11.76123;0.32419;495.03690
;406.6920;24.39680;11.73824;0.32471;494.06918
;407.1900;24.42676;11.71526;0.32521;493.10190
;407.6020;24.45145;11.69204;0.32562;492.12476
;408.0840;24.48045;11.66898;0.32610;491.15399
;408.4840;24.50442;11.64744;0.32650;490.24747
;408.9480;24.53223;11.62401;0.32697;489.26135
;409.3420;24.55590;11.60091;0.32736;488.28882
;409.8020;24.58347;11.57782;0.32782;487.31714
;410.1860;24.60648;11.55426;0.32820;486.32541
;410.5780;24.62998;11.53097;0.32860;485.34521
;410.9720;24.65372;11.50771;0.32899;484.36615
;411.3540;24.67656;11.48443;0.32937;483.38611
;411.7180;24.69838;11.46129;0.32974;482.41238
;412.0700;24.71955;11.43826;0.33009;481.44299
;412.4320;24.74137;11.41504;0.33045;480.46548
;412.7880;24.76271;11.39168;0.33081;479.48209
;413.1260;24.78286;11.36865;0.33114;478.51297
;413.4700;24.80355;11.34490;0.33149;477.51312
;413.8060;24.82370;11.32184;0.33183;476.54285
;414.1120;24.84212;11.29870;0.33213;475.56876
;414.4400;24.86185;11.27545;0.33246;474.58990
;414.7360;24.87948;11.25216;0.33275;473.60965
;415.0660;24.89927;11.22894;0.33308;472.63229
;415.3680;24.91745;11.20573;0.33339;471.65561
;415.6700;24.93569;11.18245;0.33369;470.67566
;415.9500;24.95231;11.15936;0.33397;469.70380
;416.2560;24.97066;11.13597;0.33427;468.71912
;416.5420;24.98794;11.11274;0.33456;467.74164
;416.8140;25.00414;11.08962;0.33483;466.76822
;417.1220;25.02274;11.06623;0.33514;465.78406
;417.3800;25.03816;11.04291;0.33540;464.80237
;417.6580;25.05478;11.01954;0.33568;463.81876
;417.9480;25.07230;10.99622;0.33597;462.83731
;418.1980;25.08725;10.97260;0.33622;461.84277
;418.4640;25.10321;10.94948;0.33648;460.86966
;418.7260;25.11888;10.92624;0.33674;459.89154
;419.0160;25.13634;10.90271;0.33704;458.90125
;419.2360;25.14949;10.87897;0.33725;457.90198
;419.5260;25.16701;10.85516;0.33755;456.89987
;419.7500;25.18035;10.83148;0.33777;455.90323
;419.9960;25.19529;10.80822;0.33802;454.92416
;420.2520;25.21048;10.78511;0.33827;453.95157
;420.4720;25.22363;10.76182;0.33849;452.97101
;420.7320;25.23936;10.73846;0.33875;451.98785
;420.9680;25.25347;10.71528;0.33899;451.01233
;421.1800;25.26620;10.69189;0.33920;450.02768
;421.4400;25.28175;10.66851;0.33946;449.04382
;421.6460;25.29407;10.64516;0.33966;448.06070
;421.8700;25.30758;10.62165;0.33989;447.07123
;422.0980;25.32121;10.59822;0.34012;446.08517
;422.3460;25.33609;10.57479;0.34036;445.09869
;422.5500;25.34829;10.55122;0.34057;444.10681
;422.7620;25.36115;10.52794;0.34078;443.12714
;423.0000;25.37544;10.50444;0.34102;442.13779
;423.2080;25.38787;10.48061;0.34123;441.13461
;423.4140;25.40013;10.45697;0.34143;440.13986
;423.6100;25.41203;10.43350;0.34163;439.15189
;423.8320;25.42536;10.41033;0.34185;438.17648
;424.0400;25.43786;10.38699;0.34206;437.19434
;424.2520;25.45047;10.36327;0.34227;436.19592
;424.4400;25.46177;10.33963;0.34246;435.20093
;424.6460;25.47409;10.31581;0.34266;434.19815
;424.8440;25.48599;10.29266;0.34286;433.22372
;425.0540;25.49866;10.26917;0.34307;432.23505
;425.2520;25.51050;10.24541;0.34327;431.23502
;425.4560;25.52276;10.22148;0.34348;430.22797
;425.6380;25.53364;10.19759;0.34366;429.22220
;425.8340;25.54536;10.17366;0.34385;428.21503
;426.0140;25.55618;10.15024;0.34403;427.22928
;426.1980;25.56718;10.12649;0.34422;426.22955
;426.3820;25.57830;10.10311;0.34440;425.24542
;426.5660;25.58924;10.07951;0.34458;424.25235
;426.7540;25.60061;10.05549;0.34477;423.24127
;426.9460;25.61208;10.03175;0.34496;422.24216
;427.1280;25.62314;10.00856;0.34515;421.26605
;427.3160;25.63445;9.98497;0.34534;420.27295
;427.4960;25.64527;9.96116;0.34552;419.27069
;427.6700;25.65561;9.93763;0.34569;418.28052
;427.8480;25.66631;9.91373;0.34587;417.27448
;428.0220;25.67678;9.89016;0.34604;416.28253
;428.1980;25.68730;9.86670;0.34622;415.29483
;428.3700;25.69770;9.84289;0.34639;414.29263
;428.5500;25.70840;9.81841;0.34657;413.26248
;428.7220;25.71875;9.79439;0.34674;412.25162
;428.8900;25.72879;9.77011;0.34691;411.22955
;429.0580;25.73896;9.74630;0.34708;410.22736
;429.2140;25.74829;9.72249;0.34723;409.22504
;429.3900;25.75875;9.69884;0.34741;408.22952
;429.5480;25.76820;9.67491;0.34757;407.22229
;429.7160;25.77824;9.65104;0.34773;406.21786
;429.8760;25.78792;9.62731;0.34790;405.21893
;430.0280;25.79701;9.60315;0.34805;404.20221
;430.1960;25.80706;9.57953;0.34821;403.20776
;430.3540;25.81663;9.55560;0.34837;402.20056
;430.5200;25.82649;9.53158;0.34854;401.18942
;430.6740;25.83587;9.50791;0.34869;400.19324
;430.8340;25.84550;9.48417;0.34886;399.19427
;430.9920;25.85501;9.46044;0.34901;398.19540
;431.1340;25.86356;9.43621;0.34916;397.17520
;431.2800;25.87211;9.41220;0.34930;396.16489
;431.4400;25.88179;9.38806;0.34946;395.14874
;431.5920;25.89088;9.36346;0.34961;394.11328
;431.7460;25.90015;9.33982;0.34977;393.11850
;431.8980;25.90930;9.31564;0.34992;392.10062
;432.0420;25.91791;9.29127;0.35006;391.07492
;432.1920;25.92694;9.26738;0.35021;390.06906
;432.3380;25.93567;9.24295;0.35036;389.04102
;432.4800;25.94403;9.21875;0.35050;388.02261
;432.6260;25.95288;9.19488;0.35064;387.01749
;432.7660;25.96137;9.17135;0.35079;386.02740
;432.9180;25.97046;9.14764;0.35094;385.02936
;433.0500;25.97841;9.12303;0.35107;383.99350
;433.1880;25.98667;9.09885;0.35121;382.97589
;433.3360;25.99551;9.07495;0.35136;381.96982
;433.4740;26.00383;9.05104;0.35149;380.96344
;433.6140;26.01226;9.02695;0.35163;379.94928
;433.7480;26.02033;9.00346;0.35177;378.96088
;433.8780;26.02804;8.97936;0.35190;377.94647
;434.0120;26.03605;8.95481;0.35203;376.91321
;434.1600;26.04496;8.93123;0.35218;375.92035
;434.3020;26.05357;8.90723;0.35232;374.91052
;434.4180;26.06045;8.88269;0.35244;373.87735
;434.5560;26.06870;8.85873;0.35257;372.86914
;434.6940;26.07707;8.83451;0.35271;371.84967
;434.8300;26.08526;8.80953;0.35285;370.79825
;434.9620;26.09315;8.78472;0.35298;369.75381
;435.0860;26.10056;8.76046;0.35311;368.73276
;435.2180;26.10840;8.73650;0.35324;367.72418
;435.3520;26.11647;8.71275;0.35337;366.72455
;435.4700;26.12358;8.68852;0.35349;365.70459
;435.5940;26.13100;8.66438;0.35361;364.68860
;435.7300;26.13913;8.63950;0.35375;363.64145
;435.8540;26.14666;8.61534;0.35387;362.62448
;435.9760;26.15390;8.59115;0.35399;361.60620
;436.0960;26.16107;8.56744;0.35411;360.60855
;436.2340;26.16950;8.54317;0.35426;359.58701
;436.3440;26.17614;8.51868;0.35437;358.55621
;436.4660;26.18332;8.49397;0.35449;357.51608
;436.5940;26.19103;8.47026;0.35461;356.51807
;436.7040;26.19766;8.44600;0.35472;355.49713
;436.8280;26.20496;8.42175;0.35485;354.47610
;436.9500;26.21231;8.39787;0.35497;353.47128
;437.0720;26.21973;8.37347;0.35509;352.44421
;437.1840;26.22636;8.34911;0.35520;351.41861
;437.3080;26.23383;8.32450;0.35533;350.38297
;437.4340;26.24149;8.29953;0.35545;349.33173
;437.5400;26.24783;8.27495;0.35556;348.29749
;437.6560;26.25470;8.25068;0.35568;347.27591
;437.7780;26.26211;8.22594;0.35580;346.23438
;437.8840;26.26839;8.20219;0.35590;345.23499
;437.9940;26.27497;8.17847;0.35601;344.23657
;438.1220;26.28280;8.15377;0.35614;343.19659
;438.2220;26.28866;8.12864;0.35624;342.13922
;438.3400;26.29584;8.10409;0.35636;341.10587
;438.4560;26.30277;8.07886;0.35648;340.04379
;438.5600;26.30893;8.05390;0.35658;338.99338
;438.6780;26.31605;8.02951;0.35670;337.96652
;438.7840;26.32244;8.00487;0.35680;336.92944
;438.8900;26.32872;7.98058;0.35691;335.90707
;439.0000;26.33548;7.95689;0.35702;334.90988
;439.0940;26.34104;7.93304;0.35711;333.90628
;439.2060;26.34773;7.90787;0.35723;332.84665
;439.3140;26.35431;7.88334;0.35734;331.81406
;439.4180;26.36041;7.85863;0.35744;330.77405
;439.5260;26.36699;7.83392;0.35755;329.73404
;439.6260;26.37290;7.80924;0.35765;328.69537
;439.7300;26.37918;7.78541;0.35775;327.69229
;439.8380;26.38570;7.75962;0.35786;326.60696
;439.9360;26.39150;7.73500;0.35796;325.57068
;440.0420;26.39790;7.71104;0.35806;324.56226
;440.1380;26.40364;7.68612;0.35816;323.51324
;440.2420;26.40991;7.66127;0.35826;322.46722
;440.3420;26.41589;7.63621;0.35836;321.41229
;440.4420;26.42181;7.61155;0.35846;320.37451
;440.5440;26.42803;7.58658;0.35856;319.32355
;440.6400;26.43371;7.56164;0.35866;318.27356
;440.7420;26.43999;7.53700;0.35876;317.23642
;440.8300;26.44513;7.51216;0.35885;316.19122
;440.9400;26.45183;7.48666;0.35896;315.11783
;441.0280;26.45709;7.46183;0.35905;314.07278
;441.1260;26.46301;7.43596;0.35915;312.98392
;441.2180;26.46845;7.41131;0.35924;311.94617
;441.3160;26.47431;7.38581;0.35934;310.87277
;441.4080;26.47993;7.36037;0.35943;309.80209
;441.4900;26.48477;7.33514;0.35951;308.74036
;441.5420;26.48788;7.30607;0.35956;307.51660
;441.5600;26.48925;5.67592;0.35958;238.90273
;441.5680;26.49003;4.02013;0.35960;169.20963