File: data/am2.csv
Results Table 1
,Sample,E-modulus,Tensile stress at Yield (Offset 0.2 %),Maximum Tensile stress,Tensile stress at Break (Standard),% Elongation at break at Non-proportional elongation (Standard),% Elongation at tensile strength at Non-proportional elongation (Standard),Strain hardening exponent at N Value,Area under curve total,Area under curve at tensile stress at yield
,,(GPa),(MPa),(MPa),(MPa),(%),(%),,(N-mm/mm^3),(N-mm/mm^3)
1,"Aço 1055","110.351","588.719","939.877","650.677","14.34","10.02","0.201","-----","-----"
1,Time,Displacement,Force,Tensile strain (Strain 2),Tensile stress
,(s),(mm),(kN),(mm/mm),(MPa)
"","0.0000","-0.05602","0.00661","0.00000","0.27843"
"","0.1420","-0.05154","0.04749","0.00001","1.99899"
"","0.3380","-0.03695","0.08544","0.00002","3.59613"
"","0.9660","0.00203","0.11864","0.00002","4.99381"
"","1.1700","0.01429","0.15321","0.00002","6.44876"
"","1.3220","0.02338","0.18818","0.00002","7.92052"
"","1.4660","0.03193","0.22418","0.00002","9.43597"
"","1.5500","0.03713","0.26119","0.00003","10.99357"
"","1.6280","0.04167","0.29765","0.00003","12.52807"
"","1.7080","0.04664","0.33418","0.00003","14.06593"
"","1.7940","0.05166","0.37280","0.00004","15.69140"
"","1.8720","0.05638","0.40948","0.00004","17.23523"
"","1.9580","0.06152","0.44833","0.00005","18.87060"
"","2.0360","0.06625","0.48554","0.00005","20.43648"
"","2.1140","0.07097","0.52717","0.00005","22.18905"
"","2.1920","0.07557","0.56877","0.00005","23.93995"
"","2.2680","0.08018","0.61319","0.00006","25.80950"
"","2.3460","0.08478","0.65929","0.00006","27.75000"
"","2.4100","0.08873","0.69995","0.00007","29.46125"
"","2.4660","0.09202","0.73561","0.00007","30.96213"
"","2.5320","0.09596","0.77371","0.00007","32.56605"
"","2.6080","0.10057","0.81468","0.00008","34.29019"
"","2.6720","0.10427","0.85407","0.00009","35.94813"
"","2.7240","0.10744","0.88918","0.00009","37.42628"
"","2.7760","0.11067","0.92663","0.00010","39.00220"
"","2.8280","0.11372","0.96288","0.00011","40.52819"
"","2.8800","0.11683","0.99747","0.00011","41.98400"
"","2.9320","0.12006","1.03611","0.00012","43.61051"
"","2.9840","0.12311","1.07375","0.00013","45.19484"
"","3.0360","0.12622","1.10981","0.00013","46.71255"
"","3.0880","0.12938","1.14979","0.00014","48.39510"
"","3.1400","0.13249","1.19026","0.00016","50.09860"
"","3.1920","0.13560","1.22718","0.00016","51.65267"
"","3.2440","0.13877","1.26388","0.00017","53.19722"
"","3.2960","0.14200","1.30300","0.00017","54.84387"
"","3.3560","0.14541","1.34232","0.00018","56.49903"
"","3.4240","0.14953","1.38449","0.00020","58.27402"
"","3.4820","0.15300","1.42192","0.00020","59.84957"
"","3.5400","0.15641","1.45916","0.00021","61.41678"
"","3.5920","0.15958","1.49286","0.00022","62.83522"
"","3.6440","0.16281","1.52890","0.00023","64.35229"
"","3.7060","0.16639","1.56882","0.00023","66.03231"
"","3.7580","0.16956","1.60316","0.00024","67.47797"
"","3.8140","0.17291","1.64006","0.00026","69.03096"
"","3.8680","0.17608","1.67630","0.00026","70.55656"
"","3.9300","0.17979","1.71605","0.00027","72.22947"
"","3.9820","0.18308","1.75309","0.00028","73.78837"
"","4.0340","0.18612","1.78702","0.00029","75.21666"
"","4.0920","0.18959","1.82394","0.00030","76.77074"
"","4.1460","0.19294","1.86095","0.00030","78.32854"
"","4.2000","0.19605","1.89571","0.00031","79.79148"
"","4.2620","0.19970","1.93438","0.00032","81.41936"
"","4.3140","0.20293","1.96862","0.00033","82.86035"
"","4.3680","0.20615","2.00557","0.00034","84.41547"
"","4.4380","0.21028","2.04841","0.00035","86.21856"
"","4.4900","0.21351","2.08295","0.00035","87.67268"
"","4.5500","0.21704","2.12140","0.00036","89.29075"
"","4.6260","0.22158","2.16675","0.00037","91.19980"
"","4.6780","0.22475","2.20157","0.00038","92.66534"
"","4.7420","0.22858","2.24124","0.00039","94.33509"
"","4.8100","0.23264","2.28275","0.00040","96.08230"
"","4.8660","0.23611","2.32050","0.00041","97.67107"
"","4.9420","0.24059","2.36445","0.00042","99.52108"
"","5.0160","0.24508","2.40901","0.00043","101.39641"
"","5.0820","0.24896","2.44858","0.00044","103.06226"
"","5.1520","0.25315","2.49069","0.00045","104.83440"
"","5.2200","0.25721","2.53173","0.00046","106.56210"
"","5.2940","0.26164","2.57547","0.00047","108.40303"
"","5.3660","0.26606","2.61815","0.00048","110.19929"
"","5.4440","0.27055","2.66211","0.00049","112.04973"
"","5.5160","0.27497","2.70399","0.00050","113.81239"
"","5.5780","0.27868","2.74141","0.00051","115.38731"
"","5.6560","0.28334","2.78409","0.00052","117.18391"
"","5.7260","0.28771","2.82526","0.00053","118.91692"
"","5.8040","0.29225","2.86479","0.00054","120.58052"
"","5.8760","0.29668","2.90677","0.00055","122.34756"
"","5.9480","0.30092","2.94726","0.00056","124.05202"
"","6.0260","0.30558","2.98706","0.00057","125.72714"
"","6.1040","0.31037","3.03255","0.00058","127.64186"
"","6.1860","0.31521","3.07121","0.00059","129.26910"
"","6.2640","0.31999","3.11318","0.00061","131.03548"
"","6.3480","0.32490","3.14983","0.00062","132.57828"
"","6.4260","0.32968","3.18592","0.00062","134.09731"
"","6.5300","0.33584","3.22564","0.00063","135.76904"
"","6.6180","0.34122","3.26200","0.00064","137.29959"
"","6.7120","0.34678","3.29997","0.00065","138.89754"
"","6.7980","0.35198","3.33704","0.00066","140.45773"
"","6.8960","0.35784","3.37568","0.00067","142.08418"
"","6.9820","0.36304","3.41197","0.00068","143.61166"
"","7.0740","0.36848","3.44946","0.00069","145.18985"
"","7.1560","0.37345","3.48518","0.00070","146.69308"
"","7.2520","0.37924","3.52409","0.00071","148.33101"
"","7.3400","0.38445","3.56081","0.00072","149.87642"
"","7.4240","0.38953","3.59585","0.00073","151.35144"
"","7.5100","0.39467","3.63302","0.00074","152.91574"
"","7.5980","0.39999","3.66927","0.00075","154.44165"
"","7.6820","0.40507","3.70586","0.00076","155.98164"
"","7.7760","0.41069","3.74345","0.00077","157.56374"
"","7.8580","0.41554","3.77978","0.00078","159.09329"
"","7.9500","0.42104","3.81758","0.00079","160.68394"
"","8.0300","0.42582","3.85302","0.00080","162.17561"
"","8.1280","0.43174","3.89228","0.00081","163.82837"
"","8.2120","0.43670","3.92875","0.00082","165.36333"
"","8.3000","0.44202","3.96612","0.00083","166.93611"
"","8.3780","0.44669","4.00128","0.00084","168.41600"
"","8.4720","0.45237","4.03976","0.00085","170.03600"
"","8.5600","0.45769","4.07675","0.00086","171.59264"
"","8.6400","0.46247","4.11183","0.00087","173.06926"
"","8.7220","0.46731","4.14854","0.00088","174.61455"
"","8.8120","0.47276","4.18570","0.00089","176.17851"
"","8.8960","0.47778","4.22355","0.00091","177.77179"
"","8.9880","0.48328","4.26133","0.00092","179.36159"
"","9.0680","0.48812","4.29944","0.00092","180.96602"
"","9.1580","0.49350","4.33607","0.00094","182.50781"
"","9.2360","0.49823","4.37321","0.00094","184.07094"
"","9.3240","0.50355","4.41086","0.00096","185.65569"
"","9.4020","0.50821","4.44648","0.00097","187.15477"
"","9.4900","0.51341","4.48452","0.00098","188.75597"
"","9.5680","0.51820","4.52277","0.00099","190.36615"
"","9.6600","0.52364","4.55975","0.00100","191.92226"
"","9.7380","0.52842","4.59688","0.00101","193.48521"
"","9.8320","0.53392","4.63493","0.00101","195.08681"
"","9.9100","0.53870","4.67337","0.00103","196.70490"
"","9.9980","0.54385","4.70975","0.00104","198.23621"
"","10.0780","0.54881","4.74794","0.00105","199.84351"
"","10.1760","0.55455","4.78733","0.00106","201.50127"
"","10.2540","0.55933","4.82431","0.00107","203.05775"
"","10.3380","0.56429","4.86121","0.00109","204.61121"
"","10.4160","0.56914","4.89629","0.00110","206.08777"
"","10.4980","0.57398","4.93330","0.00110","207.64534"
"","10.5840","0.57924","4.97014","0.00111","209.19595"
"","10.6660","0.58396","5.00656","0.00113","210.72910"
"","10.7480","0.58899","5.04327","0.00114","212.27419"
"","10.8300","0.59383","5.07931","0.00115","213.79100"
"","10.9100","0.59873","5.11536","0.00116","215.30824"
"","10.9920","0.60357","5.15180","0.00118","216.84233"
"","11.0760","0.60860","5.18895","0.00118","218.40599"
"","11.1540","0.61332","5.22570","0.00120","219.95274"
"","11.2400","0.61846","5.26239","0.00121","221.49698"
"","11.3180","0.62319","5.30003","0.00122","223.08144"
"","11.4100","0.62863","5.33766","0.00123","224.66531"
"","11.4880","0.63335","5.37594","0.00124","226.27634"
"","11.5780","0.63867","5.41353","0.00126","227.85866"
"","11.6560","0.64345","5.45030","0.00127","229.40619"
"","11.7400","0.64836","5.48661","0.00128","230.93451"
"","11.8200","0.65326","5.52352","0.00130","232.48825"
"","11.9060","0.65834","5.56148","0.00131","234.08569"
"","11.9840","0.66318","5.59800","0.00132","235.62280"
"","12.0660","0.66803","5.63361","0.00133","237.12169"
"","12.1460","0.67293","5.66981","0.00134","238.64560"
"","12.2320","0.67795","5.70740","0.00136","240.22757"
"","12.3100","0.68274","5.74252","0.00137","241.70575"
"","12.3960","0.68782","5.78013","0.00138","243.28877"
"","12.4780","0.69278","5.81621","0.00140","244.80775"
"","12.5600","0.69762","5.85279","0.00141","246.34711"
"","12.6440","0.70265","5.88879","0.00143","247.86234"
"","12.7260","0.70761","5.92929","0.00144","249.56703"
"","12.8140","0.71287","5.96673","0.00145","251.14291"
"","12.8920","0.71759","6.00477","0.00147","252.74414"
"","12.9800","0.72274","6.04140","0.00148","254.28615"
"","13.0580","0.72752","6.07988","0.00149","255.90549"
"","13.1460","0.73278","6.11648","0.00151","257.44614"
"","13.2240","0.73756","6.15394","0.00152","259.02283"
"","13.3160","0.74306","6.19104","0.00153","260.58432"
"","13.3980","0.74797","6.22658","0.00155","262.08035"
"","13.4920","0.75353","6.26547","0.00156","263.71722"
"","13.5720","0.75843","6.30209","0.00158","265.25833"
"","13.6640","0.76387","6.33984","0.00159","266.84750"
"","13.7540","0.76937","6.37840","0.00161","268.47043"
"","13.8520","0.77517","6.41767","0.00162","270.12317"
"","13.9340","0.78013","6.45571","0.00164","271.72449"
"","14.0240","0.78551","6.49305","0.00165","273.29596"
"","14.1020","0.79030","6.52796","0.00167","274.76553"
"","14.2020","0.79616","6.56602","0.00168","276.36734"
"","14.2800","0.80088","6.60257","0.00170","277.90591"
"","14.3780","0.80668","6.64147","0.00171","279.54327"
"","14.4560","0.81146","6.67788","0.00173","281.07584"
"","14.5540","0.81732","6.71626","0.00174","282.69119"
"","14.6340","0.82205","6.75173","0.00176","284.18402"
"","14.7260","0.82761","6.78957","0.00177","285.77682"
"","14.8100","0.83269","6.82623","0.00179","287.32004"
"","14.9060","0.83849","6.86521","0.00180","288.96063"
"","14.9860","0.84321","6.90006","0.00181","290.42743"
"","15.0780","0.84877","6.93792","0.00183","292.02087"
"","15.1640","0.85391","6.97444","0.00185","293.55807"
"","15.2540","0.85935","7.01124","0.00186","295.10718"
"","15.3440","0.86468","7.04723","0.00188","296.62201"
"","15.4360","0.87018","7.08538","0.00189","298.22778"
"","15.5280","0.87568","7.12273","0.00190","299.79959"
"","15.6240","0.88154","7.16072","0.00192","301.39874"
"","15.7240","0.88746","7.19730","0.00194","302.93854"
"","15.8280","0.89373","7.23615","0.00195","304.57361"
"","15.9360","0.90019","7.27312","0.00197","306.12979"
"","16.0420","0.90653","7.31117","0.00198","307.73141"
"","16.1520","0.91322","7.34773","0.00200","309.27023"
"","16.2580","0.91944","7.38485","0.00201","310.83246"
"","16.3580","0.92554","7.42231","0.00203","312.40924"
"","16.4680","0.93212","7.45800","0.00204","313.91144"
"","16.5700","0.93822","7.49456","0.00206","315.45029"
"","16.6700","0.94432","7.53096","0.00207","316.98227"
"","16.7740","0.95053","7.56650","0.00209","318.47812"
"","16.8780","0.95687","7.60517","0.00211","320.10599"
"","16.9920","0.96357","7.64220","0.00212","321.66443"
"","17.0940","0.96967","7.67949","0.00214","323.23416"
"","17.1980","0.97600","7.71697","0.00215","324.81149"
"","17.3080","0.98246","7.75326","0.00217","326.33917"
"","17.4040","0.98832","7.79013","0.00218","327.89111"
"","17.5080","0.99448","7.82544","0.00220","329.37723"
"","17.6040","1.00034","7.86330","0.00221","330.97086"
"","17.7160","1.00715","7.90147","0.00223","332.57727"
"","17.8260","1.01361","7.93795","0.00224","334.11273"
"","17.9300","1.01989","7.97718","0.00226","335.76422"
"","18.0360","1.02629","8.01418","0.00227","337.32153"
"","18.1400","1.03250","8.05082","0.00229","338.86359"
"","18.2380","1.03842","8.08668","0.00231","340.37292"
"","18.3460","1.04476","8.12242","0.00232","341.87735"
"","18.4480","1.05098","8.15980","0.00234","343.45074"
"","18.5520","1.05720","8.19462","0.00235","344.91611"
"","18.6580","1.06354","8.23243","0.00237","346.50769"
"","18.7620","1.06981","8.26990","0.00238","348.08496"
"","18.8680","1.07609","8.30669","0.00240","349.63342"
"","18.9720","1.08237","8.34400","0.00242","351.20374"
"","19.0800","1.08877","8.38155","0.00244","352.78418"
"","19.1880","1.09528","8.42050","0.00245","354.42352"
"","19.2920","1.10168","8.45685","0.00246","355.95358"
"","19.4000","1.10802","8.49318","0.00248","357.48294"
"","19.5040","1.11430","8.53208","0.00249","359.12027"
"","19.6140","1.12093","8.56978","0.00251","360.70670"
"","19.7200","1.12721","8.60633","0.00253","362.24539"
"","19.8260","1.13361","8.64447","0.00254","363.85052"
"","19.9380","1.14025","8.68197","0.00256","365.42899"
"","20.0380","1.14634","8.72044","0.00257","367.04840"
"","20.1500","1.15310","8.75774","0.00259","368.61832"
"","20.2540","1.15920","8.79412","0.00261","370.14951"
"","20.3500","1.16512","8.83080","0.00262","371.69327"
"","20.4600","1.17163","8.86651","0.00264","373.19662"
"","20.5640","1.17785","8.90368","0.00265","374.76083"
"","20.6700","1.18431","8.94230","0.00267","376.38666"
"","20.7860","1.19119","8.97972","0.00269","377.96170"
"","20.8820","1.19705","9.01729","0.00270","379.54291"
"","20.9980","1.20392","9.05376","0.00272","381.07794"
"","21.1060","1.21038","9.09312","0.00274","382.73474"
"","21.2000","1.21612","9.12778","0.00275","384.19345"
"","21.3100","1.22270","9.16401","0.00277","385.71826"
"","21.4140","1.22891","9.20195","0.00279","387.31540"
"","21.5180","1.23519","9.23826","0.00280","388.84351"
"","21.6300","1.24189","9.27674","0.00282","390.46317"
"","21.7380","1.24840","9.31503","0.00284","392.07492"
"","21.8480","1.25486","9.35200","0.00285","393.63092"
"","21.9520","1.26114","9.38996","0.00287","395.22873"
"","22.0560","1.26748","9.42545","0.00289","396.72269"
"","22.1700","1.27423","9.46271","0.00291","398.29102"
"","22.2700","1.28027","9.50028","0.00292","399.87210"
"","22.3800","1.28691","9.53568","0.00294","401.36227"
"","22.4880","1.29337","9.57348","0.00296","402.95328"
"","22.6020","1.30024","9.61178","0.00298","404.56531"
"","22.7080","1.30652","9.64809","0.00299","406.09344"
"","22.8120","1.31280","9.68540","0.00300","407.66385"
"","22.9200","1.31931","9.72118","0.00302","409.16995"
"","23.0340","1.32607","9.75846","0.00304","410.73926"
"","23.1380","1.33241","9.79603","0.00306","412.32050"
"","23.2480","1.33899","9.83182","0.00308","413.82672"
"","23.3620","1.34574","9.86880","0.00309","415.38321"
"","23.4660","1.35202","9.90574","0.00311","416.93814"
"","23.5780","1.35866","9.94237","0.00313","418.47995"
"","23.6820","1.36499","9.97932","0.00315","420.03519"
"","23.7940","1.37169","10.01483","0.00316","421.53006"
"","23.8960","1.37779","10.05092","0.00318","423.04892"
"","24.0020","1.38425","10.08847","0.00320","424.62927"
"","24.1180","1.39118","10.12562","0.00322","426.19299"
"","24.2220","1.39734","10.16169","0.00323","427.71118"
"","24.3280","1.40386","10.19747","0.00325","429.21747"
"","24.4380","1.41031","10.23350","0.00327","430.73373"
"","24.5440","1.41671","10.27011","0.00329","432.27484"
"","24.6560","1.42335","10.30643","0.00331","433.80353"
"","24.7640","1.42987","10.34376","0.00332","435.37457"
"","24.8700","1.43638","10.38022","0.00334","436.90927"
"","24.9920","1.44356","10.41696","0.00337","438.45593"
"","25.0960","1.44984","10.45469","0.00338","440.04364"
"","25.2040","1.45641","10.49054","0.00340","441.55289"
"","25.3240","1.46347","10.52679","0.00342","443.07864"
"","25.4300","1.46986","10.56461","0.00344","444.67023"
"","25.5420","1.47662","10.60028","0.00346","446.17175"
"","25.6600","1.48368","10.63780","0.00348","447.75098"
"","25.7740","1.49049","10.67503","0.00349","449.31812"
"","25.8820","1.49707","10.71127","0.00352","450.84338"
"","26.0020","1.50418","10.74954","0.00354","452.45435"
"","26.1120","1.51076","10.78577","0.00355","453.97897"
"","26.2280","1.51770","10.82187","0.00358","455.49850"
"","26.3400","1.52439","10.85833","0.00360","457.03308"
"","26.4500","1.53109","10.89478","0.00361","458.56735"
"","26.5660","1.53802","10.93015","0.00364","460.05609"
"","26.6820","1.54490","10.96691","0.00366","461.60355"
"","26.7900","1.55154","11.00304","0.00368","463.12415"
"","26.9120","1.55883","11.03875","0.00370","464.62701"
"","27.0280","1.56565","11.07468","0.00372","466.13953"
"","27.1360","1.57228","11.11179","0.00374","467.70132"
"","27.2620","1.57982","11.14804","0.00376","469.22711"
"","27.3760","1.58651","11.18438","0.00378","470.75696"
"","27.4860","1.59321","11.22121","0.00381","472.30719"
"","27.6120","1.60074","11.25819","0.00383","473.86343"
"","27.7280","1.60768","11.29494","0.00385","475.41040"
"","27.8400","1.61450","11.33165","0.00387","476.95554"
"","27.9660","1.62209","11.36773","0.00389","478.47415"
"","28.0860","1.62920","11.40442","0.00392","480.01865"
"","28.2020","1.63620","11.44087","0.00394","481.55249"
"","28.3240","1.64355","11.47920","0.00396","483.16617"
"","28.4500","1.65109","11.51482","0.00398","484.66537"
"","28.5620","1.65778","11.55043","0.00401","486.16415"
"","28.6800","1.66496","11.58710","0.00403","487.70767"
"","28.8040","1.67237","11.62280","0.00405","489.21008"
"","28.9240","1.67949","11.65911","0.00408","490.73868"
"","29.0400","1.68648","11.69539","0.00410","492.26578"
"","29.1640","1.69384","11.73172","0.00412","493.79456"
"","29.2820","1.70095","11.76733","0.00415","495.29346"
"","29.4000","1.70807","11.80455","0.00417","496.86029"
"","29.5280","1.71578","11.84106","0.00419","498.39709"
"","29.6500","1.72307","11.87632","0.00422","499.88092"
"","29.7720","1.73037","11.91251","0.00424","501.40448"
"","29.8860","1.73718","11.94738","0.00426","502.87183"
"","30.0120","1.74478","11.98318","0.00429","504.37881"
"","30.1320","1.75195","12.01833","0.00431","505.85843"
"","30.2520","1.75925","12.05407","0.00434","507.36276"
"","30.3820","1.76702","12.09012","0.00437","508.88016"
"","30.5040","1.77431","12.12634","0.00439","510.40457"
"","30.6260","1.78161","12.16331","0.00442","511.96063"
"","30.7600","1.78968","12.19880","0.00445","513.45447"
"","30.8880","1.79727","12.23520","0.00448","514.98639"
"","31.0100","1.80457","12.27127","0.00451","516.50488"
"","31.1360","1.81228","12.30742","0.00453","518.02618"
"","31.2660","1.82011","12.34287","0.00456","519.51849"
"","31.4040","1.82830","12.37986","0.00459","521.07550"
"","31.5260","1.83566","12.41556","0.00462","522.57782"
"","31.6500","1.84319","12.45098","0.00465","524.06860"
"","31.7920","1.85156","12.48662","0.00468","525.56897"
"","31.9200","1.85921","12.52341","0.00471","527.11731"
"","32.0440","1.86675","12.55935","0.00474","528.63007"
"","32.1800","1.87494","12.59502","0.00478","530.13135"
"","32.3160","1.88307","12.63032","0.00481","531.61737"
"","32.4500","1.89108","12.66641","0.00484","533.13635"
"","32.5880","1.89927","12.70258","0.00488","534.65857"
"","32.7200","1.90728","12.73895","0.00491","536.18970"
"","32.8600","1.91577","12.77524","0.00495","537.71716"
"","33.0000","1.92403","12.81055","0.00499","539.20331"
"","33.1340","1.93210","12.84654","0.00502","540.71796"
"","33.2700","1.94035","12.88256","0.00505","542.23438"
"","33.4120","1.94884","12.91845","0.00509","543.74481"
"","33.5560","1.95745","12.95464","0.00513","545.26813"
"","33.7020","1.96618","12.99019","0.00517","546.76447"
"","33.8420","1.97449","13.02579","0.00521","548.26306"
"","33.9740","1.98250","13.06140","0.00525","549.76178"
"","34.1300","1.99183","13.09685","0.00529","551.25378"
"","34.2660","2.00008","13.13361","0.00533","552.80103"
"","34.4180","2.00923","13.16864","0.00538","554.27551"
"","34.5720","2.01831","13.20413","0.00543","555.76935"
"","34.7200","2.02722","13.24004","0.00547","557.28064"
"","34.8620","2.03577","13.27543","0.00552","558.77051"
"","35.0080","2.04450","13.31090","0.00556","560.26331"
"","35.1560","2.05347","13.34743","0.00561","561.80084"
"","35.3140","2.06292","13.38269","0.00566","563.28510"
"","35.4640","2.07194","13.41798","0.00571","564.77051"
"","35.6140","2.08097","13.45304","0.00576","566.24585"
"","35.7740","2.09048","13.48853","0.00581","567.74005"
"","35.9320","2.10005","13.52475","0.00586","569.26428"
"","36.0980","2.10997","13.56089","0.00592","570.78558"
"","36.2560","2.11942","13.59638","0.00597","572.27924"
"","36.4080","2.12857","13.63195","0.00603","573.77643"
"","36.5660","2.13795","13.66709","0.00608","575.25555"
"","36.7200","2.14728","13.70246","0.00613","576.74408"
"","36.8920","2.15762","13.73777","0.00619","578.23065"
"","37.0520","2.16719","13.77289","0.00625","579.70874"
"","37.2220","2.17741","13.80856","0.00631","581.20990"
"","37.3920","2.18764","13.84442","0.00637","582.71954"
"","37.5600","2.19774","13.87933","0.00644","584.18884"
"","37.7300","2.20791","13.91447","0.00649","585.66809"
"","37.9020","2.21825","13.94994","0.00656","587.16071"
"","38.0800","2.22889","13.98538","0.00663","588.65259"
"","38.2560","2.23942","14.02097","0.00669","590.15063"
"","38.4280","2.24982","14.05586","0.00676","591.61914"
"","38.6040","2.26040","14.09141","0.00682","593.11548"
"","38.7820","2.27122","14.12739","0.00689","594.63000"
"","38.9660","2.28211","14.16214","0.00696","596.09259"
"","39.1500","2.29317","14.19739","0.00703","597.57623"
"","39.3380","2.30435","14.23321","0.00711","599.08380"
"","39.5220","2.31541","14.26816","0.00718","600.55511"
"","39.7200","2.32725","14.30292","0.00726","602.01801"
"","39.9060","2.33837","14.33862","0.00733","603.52063"
"","40.1060","2.35038","14.37386","0.00740","605.00385"
"","40.2880","2.36133","14.40861","0.00747","606.46643"
"","40.4880","2.37340","14.44415","0.00755","607.96228"
"","40.6740","2.38464","14.47953","0.00763","609.45148"
"","40.8760","2.39666","14.51395","0.00770","610.90039"
"","41.0700","2.40826","14.54911","0.00778","612.38025"
"","41.2920","2.42153","14.58408","0.00787","613.85223"
"","41.4860","2.43325","14.61919","0.00794","615.32983"
"","41.7020","2.44617","14.65385","0.00803","616.78876"
"","41.8900","2.45747","14.68805","0.00810","618.22839"
"","42.0940","2.46972","14.72219","0.00818","619.66528"
"","42.3000","2.48216","14.75757","0.00826","621.15436"
"","42.5420","2.49651","14.79326","0.00836","622.65649"
"","42.7500","2.50913","14.82859","0.00844","624.14386"
"","42.9660","2.52204","14.86358","0.00852","625.61646"
"","43.1840","2.53519","14.89843","0.00861","627.08331"
"","43.4180","2.54918","14.93373","0.00870","628.56915"
"","43.6340","2.56222","14.96818","0.00878","630.01898"
"","43.8440","2.57471","15.00193","0.00886","631.43970"
"","44.0980","2.58984","15.03622","0.00896","632.88300"
"","44.3140","2.60300","15.07047","0.00905","634.32483"
"","44.5460","2.61681","15.10458","0.00914","635.76019"
"","44.7780","2.63080","15.13868","0.00923","637.19580"
"","45.0160","2.64509","15.17344","0.00932","638.65887"
"","45.2720","2.66033","15.20830","0.00941","640.12604"
"","45.5080","2.67450","15.24280","0.00950","641.57825"
"","45.7460","2.68885","15.27757","0.00960","643.04156"
"","46.0040","2.70434","15.31222","0.00970","644.50012"
"","46.2460","2.71893","15.34664","0.00979","645.94861"
"","46.5080","2.73447","15.38086","0.00988","647.38916"
"","46.7520","2.74930","15.41547","0.00998","648.84576"
"","46.9920","2.76359","15.45015","0.01007","650.30560"
"","47.2720","2.78039","15.48420","0.01018","651.73865"
"","47.5160","2.79504","15.51870","0.01027","653.19080"
"","47.8020","2.81220","15.55277","0.01038","654.62494"
"","48.0700","2.82822","15.58655","0.01048","656.04688"
"","48.3280","2.84377","15.62118","0.01058","657.50427"
"","48.5940","2.85961","15.65581","0.01068","658.96198"
"","48.8700","2.87635","15.68992","0.01079","660.39740"
"","49.1280","2.89172","15.72393","0.01088","661.82892"
"","49.3880","2.90744","15.75835","0.01099","663.27808"
"","49.6880","2.92532","15.79290","0.01111","664.73193"
"","49.9300","2.93997","15.82669","0.01120","666.15436"
"","50.2160","2.95695","15.86058","0.01131","667.58093"
"","50.4880","2.97333","15.89497","0.01142","669.02820"
"","50.7660","2.99019","15.92960","0.01153","670.48572"
"","51.0480","3.00693","15.96410","0.01164","671.93805"
"","51.3220","3.02344","15.99872","0.01175","673.39502"
"","51.6140","3.04095","16.03301","0.01186","674.83856"
"","51.8860","3.05722","16.06720","0.01197","676.27771"
"","52.1680","3.07420","16.10152","0.01208","677.72205"
"","52.4720","3.09231","16.13565","0.01221","679.15863"
"","52.7380","3.10840","16.17031","0.01232","680.61761"
"","53.0200","3.12526","16.20468","0.01243","682.06427"
"","53.3240","3.14343","16.23883","0.01255","683.50153"
"","53.5920","3.15970","16.27316","0.01267","684.94659"
"","53.8940","3.17781","16.30776","0.01278","686.40265"
"","54.1860","3.19527","16.34215","0.01291","687.85052"
"","54.4860","3.21327","16.37658","0.01303","689.29962"
"","54.7740","3.23061","16.41047","0.01315","690.72583"
"","55.0780","3.24878","16.44513","0.01328","692.18469"
"","55.3660","3.26600","16.47938","0.01339","693.62653"
"","55.6720","3.28436","16.51345","0.01352","695.06049"
"","55.9820","3.30301","16.54765","0.01365","696.50012"
"","56.2720","3.32035","16.58187","0.01377","697.94006"
"","56.5560","3.33739","16.61586","0.01389","699.37091"
"","56.8680","3.35628","16.64915","0.01402","700.77216"
"","57.1760","3.37470","16.68330","0.01414","702.20959"
"","57.4680","3.39210","16.71748","0.01427","703.64813"
"","57.7600","3.40973","16.75123","0.01439","705.06866"
"","58.0800","3.42893","16.78570","0.01453","706.51947"
"","58.4020","3.44824","16.81925","0.01466","707.93176"
"","58.7020","3.46618","16.85310","0.01479","709.35651"
"","58.9940","3.48369","16.88661","0.01491","710.76697"
"","59.3060","3.50247","16.92061","0.01504","712.19794"
"","59.6320","3.52202","16.95506","0.01518","713.64801"
"","59.9340","3.54020","16.98874","0.01531","715.06555"
"","60.2480","3.55885","17.02269","0.01545","716.49463"
"","60.5360","3.57625","17.05657","0.01557","717.92072"
"","60.8640","3.59598","17.09049","0.01571","719.34827"
"","61.2000","3.61613","17.12445","0.01586","720.77783"
"","61.5200","3.63532","17.15887","0.01600","722.22668"
"","61.8320","3.65392","17.19285","0.01614","723.65686"
"","62.1560","3.67341","17.22718","0.01628","725.10175"
"","62.4760","3.69266","17.26129","0.01642","726.53735"
"","62.8020","3.71221","17.29537","0.01656","727.97180"
"","63.1260","3.73176","17.32942","0.01670","729.40527"
"","63.4480","3.75095","17.36312","0.01684","730.82336"
"","63.7680","3.77003","17.39657","0.01698","732.23138"
"","64.1020","3.79018","17.43020","0.01712","733.64703"
"","64.4380","3.81032","17.46462","0.01728","735.09589"
"","64.7360","3.82832","17.49821","0.01741","736.50934"
"","65.0620","3.84793","17.53216","0.01755","737.93854"
"","65.4080","3.86868","17.56666","0.01770","739.39069"
"","65.7420","3.88865","17.60081","0.01785","740.82788"
"","66.0880","3.90940","17.63533","0.01801","742.28094"
"","66.4260","3.92960","17.66946","0.01816","743.71747"
"","66.7720","3.95047","17.70371","0.01831","745.15918"
"","67.1080","3.97068","17.73786","0.01846","746.59656"
"","67.4360","3.99017","17.77197","0.01861","748.03241"
"","67.7740","4.01044","17.80580","0.01875","749.45624"
"","68.1260","4.03161","17.83983","0.01892","750.88873"
"","68.4740","4.05241","17.87387","0.01907","752.32129"
"","68.8120","4.07280","17.90782","0.01923","753.75031"
"","69.1740","4.09450","17.94179","0.01939","755.17999"
"","69.5100","4.11471","17.97613","0.01954","756.62537"
"","69.8480","4.13498","18.00992","0.01969","758.04755"
"","70.2200","4.15728","18.04408","0.01986","759.48547"
"","70.5640","4.17791","18.07865","0.02003","760.94080"
"","70.9120","4.19872","18.11290","0.02038","762.38214"
"","71.2720","4.22030","18.14670","0.02074","763.80481"
"","71.6220","4.24135","18.18030","0.02109","765.21912"
"","71.9820","4.26299","18.21454","0.02145","766.66010"
"","72.3300","4.28398","18.24813","0.02180","768.07434"
"","72.7000","4.30628","18.28157","0.02217","769.48169"
"","73.0500","4.32720","18.31605","0.02252","770.93292"
"","73.4160","4.34915","18.35001","0.02288","772.36237"
"","73.7800","4.37085","18.38408","0.02325","773.79633"
"","74.1300","4.39184","18.41807","0.02360","775.22717"
"","74.5300","4.41581","18.45187","0.02400","776.64960"
"","74.8760","4.43656","18.48576","0.02434","778.07593"
"","75.2420","4.45850","18.51952","0.02471","779.49707"
"","75.6260","4.48158","18.55350","0.02509","780.92725"
"","75.9880","4.50340","18.58692","0.02546","782.33405"
"","76.3600","4.52583","18.62077","0.02583","783.75891"
"","76.7500","4.54902","18.65428","0.02622","785.16931"
"","77.1140","4.57091","18.68792","0.02658","786.58527"
"","77.5040","4.59428","18.72145","0.02697","787.99658"
"","77.8740","4.61659","18.75518","0.02734","789.41626"
"","78.2600","4.63972","18.78922","0.02773","790.84875"
"","78.6260","4.66173","18.82296","0.02809","792.26923"
"","78.9920","4.68367","18.85679","0.02846","793.69281"
"","79.4120","4.70878","18.89048","0.02888","795.11115"
"","79.8000","4.73216","18.92427","0.02927","796.53320"
"","80.1860","4.75530","18.95854","0.02965","797.97571"
"","80.5680","4.77820","18.99221","0.03004","799.39307"
"","80.9840","4.80307","19.02604","0.03045","800.81683"
"","81.3800","4.82687","19.06012","0.03085","802.25104"
"","81.7600","4.84976","19.09396","0.03123","803.67535"
"","82.1800","4.87488","19.12775","0.03165","805.09784"
"","82.5860","4.89927","19.16151","0.03205","806.51886"
"","82.9700","4.92235","19.19540","0.03244","807.94543"
"","83.3900","4.94752","19.22879","0.03286","809.35052"
"","83.8120","4.97287","19.26271","0.03328","810.77856"
"","84.2020","4.99625","19.29659","0.03367","812.20428"
"","84.6340","5.02220","19.33030","0.03410","813.62329"
"","85.0360","5.04635","19.36403","0.03450","815.04303"
"","85.4820","5.07302","19.39739","0.03495","816.44720"
"","85.8760","5.09670","19.43147","0.03534","817.88141"
"","86.2840","5.12127","19.46546","0.03575","819.31226"
"","86.7620","5.14979","19.49948","0.03623","820.74426"
"","87.1580","5.17364","19.53335","0.03663","822.16980"
"","87.6300","5.20181","19.56687","0.03710","823.58069"
"","88.0540","5.22733","19.60093","0.03752","825.01416"
"","88.5040","5.25430","19.63455","0.03797","826.42920"
"","88.9060","5.27846","19.66815","0.03837","827.84369"
"","89.3800","5.30692","19.70138","0.03885","829.24243"
"","89.7960","5.33191","19.73485","0.03926","830.65106"
"","90.2660","5.36013","19.76864","0.03973","832.07336"
"","90.7480","5.38895","19.80239","0.04021","833.49390"
"","91.1780","5.41477","19.83614","0.04065","834.91437"
"","91.6460","5.44282","19.86949","0.04111","836.31812"
"","92.1220","5.47134","19.90306","0.04159","837.73102"
"","92.5660","5.49812","19.93733","0.04203","839.17358"
"","93.0440","5.52676","19.97102","0.04251","840.59149"
"","93.5420","5.55654","20.00457","0.04301","842.00385"
"","94.0000","5.58404","20.03826","0.04347","843.42163"
"","94.4760","5.61274","20.07201","0.04394","844.84241"
"","94.9680","5.64227","20.10555","0.04444","846.25391"
"","95.4720","5.67247","20.13919","0.04494","847.66998"
"","95.9780","5.70272","20.17274","0.04544","849.08221"
"","96.4680","5.73208","20.20645","0.04593","850.50085"
"","96.9200","5.75934","20.23997","0.04639","851.91193"
"","97.4880","5.79324","20.27339","0.04695","853.31848"
"","97.9620","5.82182","20.30692","0.04743","854.72955"
"","98.4800","5.85291","20.34117","0.04795","856.17126"
"","99.0140","5.88502","20.37490","0.04848","857.59094"
"","99.5360","5.91623","20.40860","0.04900","859.00964"
"","100.1180","5.95115","20.44260","0.04958","860.44061"
"","100.6520","5.98313","20.47617","0.05012","861.85376"
"","101.1960","6.01578","20.50948","0.05066","863.25549"
"","101.7260","6.04777","20.54296","0.05119","864.66461"
"","102.2680","6.08017","20.57556","0.05174","866.03693"
"","102.8180","6.11324","20.60937","0.05229","867.46014"
"","103.3980","6.14797","20.64251","0.05287","868.85510"
"","103.9720","6.18229","20.67563","0.05344","870.24908"
"","104.5240","6.21566","20.70878","0.05399","871.64423"
"","105.0980","6.24997","20.74244","0.05457","873.06104"
"","105.7120","6.28681","20.77468","0.05518","874.41809"
"","106.2880","6.32142","20.80792","0.05576","875.81720"
"","106.9120","6.35879","20.84141","0.05638","877.22668"
"","107.5020","6.39419","20.87475","0.05697","878.62994"
"","108.1320","6.43197","20.90594","0.05760","879.94281"
"","108.6940","6.46570","20.93667","0.05816","881.23627"
"","109.3320","6.50402","20.97006","0.05880","882.64172"
"","109.9340","6.54013","21.00237","0.05940","884.00159"
"","110.6020","6.58025","21.03585","0.06007","885.41071"
"","111.2640","6.61983","21.06811","0.06073","886.76880"
"","111.8560","6.65553","21.10017","0.06132","888.11798"
"","112.5400","6.69666","21.13253","0.06201","889.48010"
"","113.2240","6.73756","21.16367","0.06269","890.79083"
"","113.9100","6.77857","21.19496","0.06338","892.10767"
"","114.5760","6.81869","21.22712","0.06404","893.46136"
"","115.2700","6.86025","21.25868","0.06474","894.78986"
"","115.8900","6.89744","21.28802","0.06536","896.02484"
"","116.6460","6.94276","21.31909","0.06611","897.33270"
"","117.3620","6.98586","21.35135","0.06683","898.69031"
"","118.1180","7.03130","21.38456","0.06759","900.08826"
"","118.9160","7.07902","21.41640","0.06838","901.42859"
"","119.5980","7.11991","21.44552","0.06906","902.65411"
"","120.3180","7.16314","21.47360","0.06978","903.83588"
"","121.0600","7.20774","21.50270","0.07053","905.06061"
"","121.7640","7.25001","21.53260","0.07123","906.31927"
"","122.5760","7.29862","21.56027","0.07204","907.48389"
"","123.3360","7.34436","21.59095","0.07280","908.77521"
"","124.0420","7.38669","21.61713","0.07351","909.87738"
"","124.8700","7.43632","21.64658","0.07434","911.11688"
"","125.6620","7.48385","21.67478","0.07513","912.30383"
"","126.4600","7.53186","21.70279","0.07593","913.48285"
"","127.2620","7.57987","21.72790","0.07673","914.53943"
"","128.2080","7.63661","21.75882","0.07768","915.84106"
"","129.0720","7.68839","21.78749","0.07854","917.04761"
"","129.9580","7.74160","21.81552","0.07943","918.22742"
"","130.7420","7.78854","21.83645","0.08021","919.10864"
"","131.6760","7.84474","21.86512","0.08114","920.31531"
"","132.6360","7.90214","21.89189","0.08210","921.44208"
"","133.4440","7.95069","21.91612","0.08291","922.46210"
"","134.2960","8.00193","21.93837","0.08376","923.39844"
"","135.1400","8.05245","21.95937","0.08461","924.28210"
"","136.0640","8.10799","21.98507","0.08553","925.36389"
"","137.0700","8.16826","22.00792","0.08654","926.32562"
"","137.9560","8.22153","22.03036","0.08742","927.27020"
"","138.9220","8.27935","22.05017","0.08839","928.10419"
"","139.8720","8.33639","22.07514","0.08934","929.15521"
"","140.9200","8.39935","22.09702","0.09039","930.07605"
"","141.8420","8.45459","22.11612","0.09131","930.88007"
"","142.8300","8.51402","22.13644","0.09230","931.73535"
"","143.8900","8.57746","22.15726","0.09336","932.61145"
"","144.8240","8.63354","22.17182","0.09429","933.22437"
"","145.7820","8.69100","22.18780","0.09525","933.89691"
"","146.8240","8.75360","22.20611","0.09629","934.66760"
"","147.8320","8.81393","22.22190","0.09730","935.33252"
"","148.8400","8.87455","22.23632","0.09831","935.93939"
"","149.9740","8.94259","22.25466","0.09944","936.71118"
"","151.1060","9.01040","22.26724","0.10057","937.24066"
"","152.2040","9.07634","22.28037","0.10167","937.79340"
"","153.2320","9.13805","22.28996","0.10270","938.19696"
"","154.4140","9.20896","22.30319","0.10388","938.75397"
"","155.6180","9.28118","22.31249","0.10509","939.14545"
"","156.7480","9.34916","22.32189","0.10622","939.54089"
"","157.9800","9.42294","22.32583","0.10745","939.70673"
"","159.2460","9.49888","22.32717","0.10871","939.76331"
"","160.4520","9.57122","22.32644","0.10992","939.73236"
"","161.5840","9.63914","22.32144","0.11105","939.52191"
"","162.7520","9.70922","22.30906","0.11222","939.00092"
"","163.7300","9.76793","22.29321","0.11320","938.33368"
"","164.7580","9.82969","22.26958","0.11423","937.33929"
"","165.6420","9.88267","22.23816","0.11511","936.01666"
"","166.3580","9.92559","22.20644","0.11583","934.68170"
"","166.9280","9.95967","22.17403","0.11639","933.31726"
"","167.5240","9.99567","22.14140","0.11699","931.94409"
"","168.0020","10.02425","22.10761","0.11747","930.52197"
"","168.4620","10.05181","22.07381","0.11793","929.09918"
"","168.8560","10.07537","22.04020","0.11832","927.68463"
"","169.2620","10.09982","22.00665","0.11873","926.27246"
"","169.6400","10.12248","21.97262","0.11911","924.83997"
"","170.0100","10.14466","21.93899","0.11948","923.42462"
"","170.3640","10.16601","21.90479","0.11983","921.98523"
"","170.7000","10.18616","21.87093","0.12017","920.55981"
"","171.0320","10.20607","21.83673","0.12050","919.12036"
"","171.3200","10.22329","21.80206","0.12079","917.66089"
"","171.6300","10.24182","21.76749","0.12110","916.20612"
"","171.9540","10.26131","21.73336","0.12142","914.76929"
"","172.2580","10.27967","21.69949","0.12173","913.34375"
"","172.5400","10.29647","21.66485","0.12201","911.88580"
"","172.8220","10.31339","21.63084","0.12229","910.45422"
"","173.1180","10.33133","21.59647","0.12259","909.00751"
"","173.3780","10.34669","21.56167","0.12284","907.54303"
"","173.6720","10.36433","21.52716","0.12314","906.09021"
"","173.9360","10.38035","21.49332","0.12340","904.66583"
"","174.2080","10.39649","21.45878","0.12367","903.21234"
"","174.4600","10.41168","21.42450","0.12393","901.76917"
"","174.7340","10.42818","21.39025","0.12420","900.32788"
"","174.9920","10.44361","21.35574","0.12446","898.87500"
"","175.2440","10.45868","21.32157","0.12471","897.43713"
"","175.4880","10.47338","21.28678","0.12496","895.97266"
"","175.7540","10.48935","21.25242","0.12522","894.52631"
"","175.9860","10.50328","21.21768","0.12545","893.06409"
"","176.2440","10.51877","21.18357","0.12571","891.62848"
"","176.4800","10.53276","21.14909","0.12594","890.17731"
"","176.7140","10.54693","21.11488","0.12618","888.73706"
"","176.9600","10.56157","21.08021","0.12643","887.27802"
"","177.1800","10.57485","21.04612","0.12665","885.84320"
"","177.4140","10.58896","21.01166","0.12688","884.39252"
"","177.6600","10.60373","20.97690","0.12713","882.92944"
"","177.8740","10.61652","20.94186","0.12734","881.45465"
"","178.1020","10.63015","20.90703","0.12757","879.98853"
"","178.3560","10.64552","20.87234","0.12782","878.52844"
"","178.5660","10.65808","20.83763","0.12803","877.06769"
"","178.7760","10.67069","20.80245","0.12824","875.58685"
"","178.9980","10.68396","20.76733","0.12846","874.10883"
"","179.2340","10.69807","20.73186","0.12870","872.61578"
"","179.4560","10.71141","20.69742","0.12892","871.16626"
"","179.6520","10.72313","20.66249","0.12912","869.69592"
"","179.8800","10.73694","20.62804","0.12935","868.24573"
"","180.1020","10.75015","20.59310","0.12957","866.77515"
"","180.3020","10.76229","20.55775","0.12977","865.28748"
"","180.4960","10.77383","20.52334","0.12996","863.83917"
"","180.7020","10.78626","20.48870","0.13017","862.38092"
"","180.9020","10.79822","20.45424","0.13037","860.93036"
"","181.1260","10.81173","20.41961","0.13059","859.47272"
"","181.3220","10.82339","20.38479","0.13079","858.00745"
"","181.5140","10.83493","20.34956","0.13098","856.52454"
"","181.7080","10.84647","20.31480","0.13117","855.06165"
"","181.9040","10.85837","20.27998","0.13137","853.59576"
"","182.1060","10.87039","20.24463","0.13157","852.10797"
"","182.3080","10.88270","20.20939","0.13178","850.62457"
"","182.5040","10.89436","20.17403","0.13197","849.13647"
"","182.7040","10.90638","20.13844","0.13217","847.63824"
"","182.8900","10.91750","20.10366","0.13236","846.17450"
"","183.0760","10.92874","20.06863","0.13254","844.69989"
"","183.2540","10.93932","20.03359","0.13272","843.22516"
"","183.4420","10.95057","19.99894","0.13291","841.76666"
"","183.6200","10.96121","19.96371","0.13309","840.28381"
"","183.8080","10.97257","19.92886","0.13327","838.81677"
"","183.9840","10.98303","19.89379","0.13345","837.34076"
"","184.1720","10.99433","19.85807","0.13364","835.83734"
"","184.3480","11.00497","19.82341","0.13382","834.37872"
"","184.5320","11.01597","19.78869","0.13400","832.91705"
"","184.7100","11.02674","19.75389","0.13418","831.45245"
"","184.8840","11.03714","19.71883","0.13435","829.97662"
"","185.0600","11.04772","19.68330","0.13453","828.48145"
"","185.2240","11.05747","19.64823","0.13469","827.00494"
"","185.4180","11.06919","19.61259","0.13489","825.50507"
"","185.5860","11.07923","19.57709","0.13505","824.01068"
"","185.7620","11.08987","19.54197","0.13523","822.53278"
"","185.9280","11.09986","19.50628","0.13540","821.03052"
"","186.0940","11.10966","19.47090","0.13556","819.54120"
"","186.2620","11.11983","19.43554","0.13573","818.05292"
"","186.4300","11.12981","19.39964","0.13590","816.54175"
"","186.6060","11.14046","19.36514","0.13607","815.08990"
"","186.7660","11.15002","19.32995","0.13623","813.60864"
"","186.9280","11.15971","19.29452","0.13639","812.11707"
"","187.0900","11.16945","19.25906","0.13656","810.62494"
"","187.2520","11.17908","19.22397","0.13672","809.14771"
"","187.4160","11.18900","19.18837","0.13688","807.64929"
"","187.5760","11.19863","19.15319","0.13704","806.16858"
"","187.7320","11.20802","19.11818","0.13720","804.69519"
"","187.8860","11.21734","19.08252","0.13735","803.19415"
"","188.0360","11.22620","19.04746","0.13750","801.71832"
"","188.1960","11.23582","19.01227","0.13766","800.23724"
"","188.3480","11.24491","18.97566","0.13781","798.69617"
"","188.5060","11.25441","18.94002","0.13797","797.19629"
"","188.6700","11.26428","18.90429","0.13814","795.69244"
"","188.8180","11.27307","18.86872","0.13828","794.19507"
"","188.9780","11.28275","18.83323","0.13844","792.70148"
"","189.1320","11.29208","18.79767","0.13860","791.20441"
"","189.2860","11.30135","18.76181","0.13875","789.69519"
"","189.4280","11.30990","18.72548","0.13890","788.16595"
"","189.5700","11.31827","18.68863","0.13904","786.61499"
"","189.7200","11.32724","18.65291","0.13919","785.11145"
"","189.8720","11.33639","18.61761","0.13934","783.62579"
"","190.0200","11.34524","18.58247","0.13949","782.14661"
"","190.1660","11.35414","18.54710","0.13963","780.65778"
"","190.3060","11.36263","18.51117","0.13978","779.14575"
"","190.4420","11.37059","18.47480","0.13991","777.61475"
"","190.5840","11.37914","18.44003","0.14005","776.15125"
"","190.7240","11.38757","18.40482","0.14019","774.66943"
"","190.8660","11.39600","18.36849","0.14033","773.14032"
"","191.0040","11.40437","18.33346","0.14047","771.66565"
"","191.1380","11.41238","18.29792","0.14061","770.16962"
"","191.2800","11.42081","18.26175","0.14075","768.64758"
"","191.4200","11.42936","18.22596","0.14089","767.14099"
"","191.5580","11.43761","18.19037","0.14103","765.64294"
"","191.6920","11.44562","18.15423","0.14116","764.12177"
"","191.8200","11.45328","18.11941","0.14129","762.65637"
"","191.9560","11.46141","18.08315","0.14142","761.13000"
"","192.1040","11.47031","18.04644","0.14157","759.58484"
"","192.2320","11.47821","18.01138","0.14170","758.10931"
"","192.3480","11.48496","17.97640","0.14181","756.63702"
"","192.4840","11.49303","17.94057","0.14195","755.12866"
"","192.6280","11.50182","17.90452","0.14210","753.61145"
"","192.7520","11.50930","17.86844","0.14222","752.09265"
"","192.8760","11.51665","17.83179","0.14234","750.54999"
"","193.0120","11.52484","17.79521","0.14248","749.01031"
"","193.1400","11.53261","17.75879","0.14261","747.47742"
"","193.2600","11.53973","17.72303","0.14273","745.97223"
"","193.3880","11.54738","17.68683","0.14286","744.44861"
"","193.5160","11.55504","17.65046","0.14298","742.91791"
"","193.6440","11.56275","17.61449","0.14311","741.40387"
"","193.7600","11.56968","17.57835","0.14323","739.88275"
"","193.8820","11.57710","17.54331","0.14335","738.40771"
"","194.0080","11.58463","17.50768","0.14348","736.90833"
"","194.1320","11.59205","17.47007","0.14360","735.32520"
"","194.2500","11.59916","17.43409","0.14372","733.81061"
"","194.3740","11.60645","17.39661","0.14384","732.23328"
"","194.5040","11.61435","17.36038","0.14397","730.70825"
"","194.6180","11.62116","17.32429","0.14408","729.18915"
"","194.7400","11.62846","17.28706","0.14421","727.62225"
"","194.8640","11.63593","17.25028","0.14433","726.07404"
"","194.9780","11.64275","17.21440","0.14444","724.56384"
"","195.0960","11.64986","17.17687","0.14456","722.98407"
"","195.2200","11.65728","17.13927","0.14469","721.40137"
"","195.3320","11.66397","17.10303","0.14480","719.87628"
"","195.4500","11.67109","17.06664","0.14492","718.34442"
"","195.5700","11.67832","17.02932","0.14504","716.77374"
"","195.6800","11.68484","16.99382","0.14515","715.27942"
"","195.7980","11.69195","16.95804","0.14526","713.77344"
"","195.9100","11.69877","16.92302","0.14538","712.29956"
"","196.0160","11.70499","16.88531","0.14548","710.71246"
"","196.1320","11.71198","16.84817","0.14560","709.14899"
"","196.2460","11.71898","16.81152","0.14572","707.60651"
"","196.3540","11.72532","16.77327","0.14582","705.99634"
"","196.4740","11.73249","16.73653","0.14594","704.45013"
"","196.5880","11.73955","16.69925","0.14606","702.88074"
"","196.6940","11.74577","16.66012","0.14616","701.23395"
"","196.8040","11.75240","16.62432","0.14627","699.72705"
"","196.9100","11.75874","16.58760","0.14638","698.18127"
"","197.0180","11.76520","16.55022","0.14649","696.60815"
"","197.1300","11.77195","16.51326","0.14660","695.05231"
"","197.2340","11.77805","16.47552","0.14670","693.46405"
"","197.3440","11.78469","16.43900","0.14681","691.92688"
"","197.4480","11.79103","16.40213","0.14692","690.37506"
"","197.5540","11.79730","16.36478","0.14702","688.80304"
"","197.6620","11.80382","16.32869","0.14713","687.28387"
"","197.7680","11.81022","16.28800","0.14724","685.57135"
"","197.8720","11.81644","16.25020","0.14734","683.97998"
"","197.9780","11.82277","16.21227","0.14745","682.38373"
"","198.0820","11.82893","16.17308","0.14755","680.73419"
"","198.1920","11.83563","16.13587","0.14766","679.16803"
"","198.2840","11.84113","16.09988","0.14775","677.65314"
"","198.3880","11.84735","16.06240","0.14785","676.07544"
"","198.4900","11.85357","16.02438","0.14796","674.47516"
"","198.5820","11.85907","15.98790","0.14805","672.93976"
"","198.6840","11.86528","15.95038","0.14815","671.36072"
"","198.7740","11.87043","15.91243","0.14824","669.76324"
"","198.8760","11.87658","15.87552","0.14834","668.20959"
"","198.9700","11.88221","15.83729","0.14844","666.60040"
"","199.0720","11.88842","15.79912","0.14854","664.99371"
"","199.1600","11.89362","15.76218","0.14863","663.43921"
"","199.2560","11.89936","15.72572","0.14872","661.90442"
"","199.3380","11.90433","15.68943","0.14880","660.37683"
"","199.4300","11.90995","15.65306","0.14890","658.84619"
"","199.5100","11.91473","15.61706","0.14898","657.33087"
"","199.6020","11.92017","15.57819","0.14907","655.69501"
"","199.6820","11.92501","15.54001","0.14915","654.08795"
"","199.7560","11.92950","15.50209","0.14922","652.49182"
"","199.8080","11.93255","15.46500","0.14927","650.93060"
"","199.8600","11.93577","15.41933","0.14933","649.00824"
"","199.8940","11.93781","15.27773","0.14936","643.04828"
"","199.9120","11.93990","9.09455","0.14940","382.79474"